Workbook

Sheet Kangatang

Sheet BIA
B3: TẬP ĐOÀN CN THAN – KS VIỆT NAM | H3: CỘNG HÒA XÃ HỘI CHỦ NGHĨA VIỆT NAM
B4: CÔNG TY THAN DƯƠNG HUY-TKV | H4: Độc lập – Tự do – Hạnh phúc
J6: Quảng Ninh, ngày tháng 10 năm 2026
B12: KẾ HOẠCH SẢN XUẤT NĂM 2027
B14: (Kèm theo QĐ số: /QĐ-KCM ngày / /2026)
B18: Phòng KCM Phòng CV Phòng TĐ Phòng ĐK PGĐ SX PGĐ Cơ điện PGĐ Kỹ thuật
B22: Nguyễn Văn Thúy Nguyễn Văn Hương Đặng Văn Thiện Phạm Văn Thương Nguyễn Chí Trưởng Bùi Xuân Phương Trần Quang Vinh
B24: Nơi nhận:
B25: - Các Đ/c PGĐ (e-copy);
B26: - Các phòng ban (e-copy);
B27: - Phân xưởng (e-copy);
B28: - Khối đảng đoàn thể (e-copy);
B29: - Lưu: KCM, VP.

Sheet TONG_HOP
A1: PHỤ LỤC 1: CÁC CHỈ TIÊU KTCN CHỦ YẾU NĂM 2027
A3: TT | B3: TÊN CHỈ TIÊU | C3: ĐƠN VỊ TÍNH | D3: Khối lượng KH 2027 | E3: GHI CHÚ
A4: A | B4: SẢN LƯỢNG | E4: 0.0499999 | F4: IN
A5: I | B5: THAN NGUYÊN KHAI | C5: Tấn | D5: =D6 -> 2500000 | F5: IN
A6: 2 | B6: Than nguyên khai hầm lò | C6: Tấn | D6: =D7+D12 -> 2500000 | F6: IN
A7: 2.1 | B7: Than lò chợ: | C7: Tấn | D7: =SUM(D8:D11) -> 2216300 | F7: IN
B8: + Lò chợ máy khấu | C8: Tấn | D8: =SUMIFS(KH_LC!$V$22:$V$186,KH_LC!$K$22:$K$186,"CGH")+SUMIFS(KH_LC!$V$22:$V$186,KH_LC!$K$22:$K$186,"CGHD") -> 780000 | F8: IN
B9: + Lò chợ giá khung, giá xích | C9: Tấn | D9: =SUMIFS(KH_LC!$V$22:$V$186,KH_LC!$K$22:$K$186,"GK")+SUMIFS(KH_LC!$V$22:$V$186,KH_LC!$K$22:$K$186,"GX") -> 1281200 | F9: IN
B10: + Lò chợ giàn mềm | C10: Tấn | D10: =SUMIFS(KH_LC!$V$22:$V$186,KH_LC!$K$22:$K$186,"ZRY") -> 155100 | F10: IN
B11: + Khai thác lò dọc vỉa phân tầng, ngang nghiêng | C11: Tấn | F11: IN
A12: 2.2 | B12: Than đào lò, xén lò: | C12: Tấn | D12: =D13+D14 -> 283700 | F12: IN
B13: + Than đào lò chuẩn bị sản xuất | C13: Tấn | D13: =TH_PX2027!F8 -> 273000 | F13: IN
B14: + Than xén lò | C14: Tấn | D14: =TH_PX2027!G8 -> 10700 | F14: IN
A15: 3 | B15: Độ tro bình quân than nguyên khai | C15: % | F15: IN
A16: - | B16: Độ tro bình quân than nguyên khai hầm lò | C16: % | F16: IN
A17: 2 | B17: Mét lò CBSX | C17: m | D17: =KH_ĐL!I14 -> 25400 | F17: IN
A18: 2.1 | B18: Theo tính chất đất đá | F18: IN
B19: + Lò đá | C19: m | D19: =KH_ĐL!J14 -> 8421 | F19: IN
B20: * Tiết diện bình quân lò đá | C20: m2 | D20: {=SUMPRODUCT((KH_ĐL!$CE$18:$CE$412="Lò")*KH_ĐL!$G$18:$G$412*KH_ĐL!$J$18:$J$412)/D19} -> 16.960017 | F20: IN
B21: + Lò than | C21: m | D21: =KH_ĐL!K14 -> 16979 | F21: IN
B22: * Tiết diện bình quân lò than | C22: m2 | D22: {=SUMPRODUCT((KH_ĐL!$CE$18:$CE$412="Lò")*KH_ĐL!$G$18:$G$412*KH_ĐL!$K$18:$K$412)/D21} -> 13.209341 | F22: IN
B23: + Mét lò đào CGH đồng bộ (máy Combai) | C23: m | D23: =KH_ĐL!I417 -> 1500 | F23: IN
B24: + Mét lò đào bán CGH (xe khoan + máy xúc) | C24: m | D24: =KH_ĐL!I419 -> 1600 | F24: IN
A25: 2.2 | B25: Theo vật liệu chống | D25: =SUM(D26:D28) -> 25400 | F25: IN
B26: + Mét lò chống neo | C26: m | D26: =SUMIFS(KH_ĐL!$I$18:$I$412,KH_ĐL!$CE$18:$CE$412,"Lò",KH_ĐL!$D$18:$D$412,"Neo") -> 1756 | F26: IN
B27: + Mét lò chống sắt | C27: m | D27: =SUMIFS(KH_ĐL!$I$18:$I$412,KH_ĐL!$CE$18:$CE$412,"Lò",KH_ĐL!$D$18:$D$412,"Thép") -> 22692 | F27: IN
B28: + Mét lò chống gỗ | C28: m | D28: =SUMIFS(KH_ĐL!$I$18:$I$412,KH_ĐL!$CE$18:$CE$412,"Lò",KH_ĐL!$D$18:$D$412,"Gỗ") -> 952 | F28: IN
A29: 2.3 | B29: Theo công đoạn sản xuất | C29: m | D29: =D30+D39 -> 25400 | F29: IN
A30: * | B30: Lò than: | C30: m | D30: =D31+D34+D37 -> 16979 | F30: IN
B31: -Lò than chống sắt: | C31: " | D31: =SUMIFS(KH_ĐL!$K$18:$K$412,KH_ĐL!$CE$18:$CE$412,"Lò",KH_ĐL!$D$18:$D$412,"Thép") -> 14609 | F31: IN
B32: Trong đó: + Tiết diện bình quân | C32: m2 | D32: {=SUMPRODUCT((KH_ĐL!$CE$18:$CE$412="Lò")*(KH_ĐL!$D$18:$D$412="Thép")*KH_ĐL!$G$18:$G$412*KH_ĐL!$K$18:$K$412)/D31} -> 13.784735 | F32: IN
B33: + Đào CGH đồng bộ (máy combai) | C33: m | D33: =SUMIFS(KH_ĐL!$K$18:$K$412,KH_ĐL!$CE$18:$CE$412,"Lò",KH_ĐL!$D$18:$D$412,"Thép",KH_ĐL!$E$18:$E$412,"EBH") -> 1340 | F33: IN
B34: -Lò than chống neo: | C34: m | D34: =SUMIFS(KH_ĐL!$K$18:$K$412,KH_ĐL!$CE$18:$CE$412,"Lò",KH_ĐL!$D$18:$D$412,"Neo") -> 1471 | F34: IN
B35: Trong đó: + Tiết diện bình quân | C35: m2 | D35: {=SUMPRODUCT((KH_ĐL!$CE$18:$CE$412="Lò")*(KH_ĐL!$D$18:$D$412="Neo")*KH_ĐL!$G$18:$G$412*KH_ĐL!$K$18:$K$412)/D34} -> 12.267573 | F35: IN
B36: + Đào CGH đồng bộ (máy combai) | C36: m | D36: =SUMIFS(KH_ĐL!$K$18:$K$412,KH_ĐL!$CE$18:$CE$412,"Lò",KH_ĐL!$D$18:$D$412,"Neo",KH_ĐL!$E$18:$E$412,"EBH") -> 0 | F36: IN
B37: -Lò than chống gỗ: | C37: m | D37: =SUMIFS(KH_ĐL!$K$18:$K$412,KH_ĐL!$CE$18:$CE$412,"Lò",KH_ĐL!$D$18:$D$412,"Gỗ") -> 899 | F37: IN
B38: + Tiết diện bình quân | C38: m2 | D38: {=SUMPRODUCT((KH_ĐL!$CE$18:$CE$412="Lò")*(KH_ĐL!$D$18:$D$412="Gỗ")*KH_ĐL!$G$18:$G$412*KH_ĐL!$K$18:$K$412)/D37} -> 5.4 | F38: IN
A39: * | B39: Lò đá: | C39: m | D39: =D40+D46+D52 -> 8421 | F39: IN
B40: -Lò đá chống sắt: | C40: m | D40: =SUMIFS(KH_ĐL!$J$18:$J$412,KH_ĐL!$CE$18:$CE$412,"Lò",KH_ĐL!$D$18:$D$412,"Thép") -> 8083 | F40: IN
B41: Trong đó: + Tiết diện bình quân | C41: m2 | D41: {=SUMPRODUCT((KH_ĐL!$CE$18:$CE$412="Lò")*(KH_ĐL!$D$18:$D$412="Thép")*KH_ĐL!$G$18:$G$412*KH_ĐL!$J$18:$J$412)/D40} -> 17.233527 | F41: IN
...

Sheet TH_PX2027
A1: CÔNG TY THAN DƯƠNG HUY-TKV | AO1: CÔNG TY THAN DƯƠNG HUY-TKV
A2: TỔNG HỢP MÉT LÒ, TẤN THAN NĂM 2027 | AO2: TỔNG HỢP MÉT LÒ, TẤN THAN NĂM 2025 | AY2: =2400000-AS8-AT8-AR8 -> 0.05 | AZ2: NĂM 2024
D4: =2500000-D8 -> 0 | H4: =2500000-D8 -> 0 | J4: =7500-J8 -> 0 | AH4: =AH8+AB8 -> 1200400
A5: Stt | C5: Tên PX | D5: SL (tấn) | E5: SL năm 2027 | H5: Mét lò năm 2027 | K5: QI-2026 | Q5: QII-2026 | V5: Tổng 6T-2026 | AB5: QIII-2026 | AH5: QIV-2026 | AM5: Ghi chú | AO5: Stt | AP5: Tên PX | AQ5: SL (tấn) | AR5: Sản lượng (tấn) | AU5: Mét lò (m) | AX5: Tổng đào+xén | BA5: Tên PX | BB5: Cộng sản lượng (tấn) | BC5: Sản lượng (tấn) | BG5: Mét lò (m) | BK5: Ghi chú
F6: ĐL | G6: XL | I6: ĐL | J6: XL | L6: KT Lò chợ | M6: SL đào, xén lò | N6: ĐL | O6: XL | R6: KT Lò chợ | S6: SL đào, xén lò | T6: ĐL | U6: XL | V6: Sản lượng | X6: M.đào | Z6: M.xén | AC6: KT Lò chợ | AD6: SL đào, xén lò | AE6: ĐL | AF6: XL | AI6: KT Lò chợ | AJ6: SL đào, xén lò | AK6: ĐL | AL6: XL
E7: L.Chợ | F7: Đ.Lò | G7: X.lò | H7: Tổng | I7: Đào | J7: Xén | K7: SL | N7: Mét đào | O7: Mét xén | Q7: SL | T7: Mét đào | U7: Mét xén | V7: SL | W7: % | X7: M.đào | Y7: % | Z7: M.xén | AA7: % | AB7: SL | AE7: Mét đào | AF7: Mét xén | AH7: SL | AK7: Mét đào | AL7: Mét xén | AR7: Than chợ | AS7: Lò CBSX | AT7: Xén lò | AU7: CBSX | AV7: Neo | AW7: Xén | BC7: Than chợ | BD7: Lò CBSX | BE7: Xén lò | BF7: Đ.lò CN | BG7: CBSX | BH7: Neo | BI7: Xén | BJ7: CN
C8: CỘNG | D8: =SUM(D9:D28) -> 2500000 | E8: =SUM(E9:E28) -> 2216300 | F8: =SUM(F9:F28) -> 273000 | G8: =SUM(G9:G28) -> 10700 | H8: =SUM(H9:H28) -> 32900 | I8: =SUM(I9:I28) -> 25400 | J8: =SUM(J9:J28) -> 7500 | K8: =SUM(K9:K28)+200 -> 623000 | L8: =SUM(L9:L28) -> 551200 | M8: =SUM(M9:M28) -> 71900 | N8: =SUM(N9:N28) -> 6460 | O8: =SUM(O9:O28) -> 1939 | P8: =SUM(P9:P28) -> 0 | Q8: =SUM(Q9:Q28)+400 -> 676300 | R8: =SUM(R9:R28) -> 592600 | S8: =SUM(S9:S28) -> 83300 | T8: =SUM(T9:T28) -> 7250 | U8: =SUM(U9:U28) -> 2058 | V8: =K8+Q8 -> 1299300 | W8: =V8*100/D8 -> 51.972 | X8: =N8+T8 -> 13710 | Y8: =X8*100/I8 -> 53.976378 | Z8: =O8+U8 -> 3997 | AA8: =Z8*100/J8 -> 53.293333 | AB8: =SUM(AB9:AB28) -> 606100 | AC8: =SUM(AC9:AC28) -> 531400 | AD8: =SUM(AD9:AD28) -> 74700 | AE8: =SUM(AE9:AE28) -> 6693 | AF8: =SUM(AF9:AF28) -> 1828 | AG8: =SUM(AG9:AG28) -> 0 | AH8: =SUM(AH9:AH28)-600 -> 594300 | AI8: =SUM(AI9:AI28) -> 541100 | AJ8: =SUM(AJ9:AJ28) -> 53800 | AK8: =SUM(AK9:AK28) -> 4997 | AL8: =SUM(AL9:AL28) -> 1600 | AN8: % | AP8: CỘNG | AQ8: 2400000 | AR8: 2106000 | AS8: 281530 | AT8: 12469.95 | AU8: 25409.9 | AV8: 2004 | AW8: 7300 | BA8: CỘNG | BB8: 2500000.3 | BC8: 2211100 | BD8: 275300 | BE8: 13600.32 | BF8: 0 | BG8: 26325 | BH8: 2842 | BI8: 7300 | BJ8: 0
A9: 1 | B9: KT1. | C9: PX Than 1 | D9: =SUM(E9:G9) -> 179000 | E9: =SUM(L9,R9,AC9,AI9) -> 170100 | F9: =SUMIFS(KH_ĐL!$L:$L,KH_ĐL!$CF:$CF,$B9&F$6) -> 8700 | G9: =SUMIFS(KH_ĐL!$L:$L,KH_ĐL!$CF:$CF,$B9&G$6) -> 200 | H9: =SUM(I9:J9) -> 1001 | I9: =SUMIFS(KH_ĐL!$I:$I,KH_ĐL!$CF:$CF,$B9&I$6) -> 896 | J9: =SUMIFS(KH_ĐL!$I:$I,KH_ĐL!$CF:$CF,$B9&J$6) -> 105 | K9: =SUM(L9:M9) -> 44700 | L9: =SUMIFS(KH_LC!$AA:$AA,KH_LC!$AQ:$AQ,$B9&L$6) -> 41800 | M9: =SUMIFS(KH_LC!$AA:$AA,KH_LC!$AQ:$AQ,$B9&M$6) -> 2900 | N9: =SUMIFS(KH_ĐL!$V:$V,KH_ĐL!$CF:$CF,$B9&N$6) -> 290 | O9: =SUMIFS(KH_ĐL!$V:$V,KH_ĐL!$CF:$CF,$B9&O$6) -> 40 | Q9: =SUM(R9:S9) -> 49100 | R9: =SUMIFS(KH_LC!$AE:$AE,KH_LC!$AQ:$AQ,$B9&R$6) -> 47300 | S9: =SUMIFS(KH_LC!$AE:$AE,KH_LC!$AQ:$AQ,$B9&S$6) -> 1800 | T9: =SUMIFS(KH_ĐL!$AH:$AH,KH_ĐL!$CF:$CF,$B9&T$6) -> 195 | U9: =SUMIFS(KH_ĐL!$AH:$AH,KH_ĐL!$CF:$CF,$B9&U$6) -> 0 | V9: =K9+Q9 -> 93800 | X9: =N9+T9 -> 485 | Z9: =O9+U9 -> 40 | AB9: =SUM(AC9:AD9) -> 44100 | AC9: =SUMIFS(KH_LC!$AI:$AI,KH_LC!$AQ:$AQ,$B9&AC$6) -> 41400 | AD9: =SUMIFS(KH_LC!$AI:$AI,KH_LC!$AQ:$AQ,$B9&AD$6) -> 2700 | AE9: =SUMIFS(KH_ĐL!$AT:$AT,KH_ĐL!$CF:$CF,$B9&AE$6) -> 271 | AF9: =SUMIFS(KH_ĐL!$AT:$AT,KH_ĐL!$CF:$CF,$B9&AF$6) -> 0 | AH9: =SUM(AI9:AJ9) -> 41100 | AI9: =SUMIFS(KH_LC!$AM:$AM,KH_LC!$AQ:$AQ,$B9&AI$6) -> 39600 | AJ9: =SUMIFS(KH_LC!$AM:$AM,KH_LC!$AQ:$AQ,$B9&AJ$6) -> 1500 | AK9: =SUMIFS(KH_ĐL!$BF:$BF,KH_ĐL!$CF:$CF,$B9&AK$6) -> 140 | AL9: =SUMIFS(KH_ĐL!$BF:$BF,KH_ĐL!$CF:$CF,$B9&AL$6) -> 65 | AN9: % | AO9: 1 | AP9: PX Than 1 | AQ9: 150600 | AR9: 148000 | AS9: 1300 | AT9: 1277.7 | AU9: 125 | AV9: 0 | AW9: 360 | AX9: =AU9+AW9 -> 485 | AY9: KT1 | AZ9: PX1 | BA9: PX Than 1 | BB9: 200500 | BC9: 195900 | BD9: 3600 | BE9: 1008 | BF9: 0 | BG9: 383 | BH9: 21 | BI9: 390 | BJ9: 0 | BL9: {=_xlfn.UNIQUE(KH_ĐL!CC:CC)} -> 0
A10: 2 | B10: KT2. | C10: PX Than 2 | D10: =SUM(E10:G10) -> 165000 | E10: =SUM(L10,R10,AC10,AI10) -> 162300 | F10: =SUMIFS(KH_ĐL!$L:$L,KH_ĐL!$CF:$CF,$B10&F$6)-100 -> 2400 | G10: =SUMIFS(KH_ĐL!$L:$L,KH_ĐL!$CF:$CF,$B10&G$6) -> 300 | H10: =SUM(I10:J10) -> 550 | I10: =SUMIFS(KH_ĐL!$I:$I,KH_ĐL!$CF:$CF,$B10&I$6) -> 267 | J10: =SUMIFS(KH_ĐL!$I:$I,KH_ĐL!$CF:$CF,$B10&J$6) -> 283 | K10: =SUM(L10:M10) -> 39500 | L10: =SUMIFS(KH_LC!$AA:$AA,KH_LC!$AQ:$AQ,$B10&L$6) -> 37500 | M10: =SUMIFS(KH_LC!$AA:$AA,KH_LC!$AQ:$AQ,$B10&M$6) -> 2000 | N10: =SUMIFS(KH_ĐL!$V:$V,KH_ĐL!$CF:$CF,$B10&N$6) -> 167 | O10: =SUMIFS(KH_ĐL!$V:$V,KH_ĐL!$CF:$CF,$B10&O$6) -> 43 | Q10: =SUM(R10:S10) -> 44500 | R10: =SUMIFS(KH_LC!$AE:$AE,KH_LC!$AQ:$AQ,$B10&R$6) -> 43800 | S10: =SUMIFS(KH_LC!$AE:$AE,KH_LC!$AQ:$AQ,$B10&S$6) -> 700 | T10: =SUMIFS(KH_ĐL!$AH:$AH,KH_ĐL!$CF:$CF,$B10&T$6) -> 100 | U10: =SUMIFS(KH_ĐL!$AH:$AH,KH_ĐL!$CF:$CF,$B10&U$6) -> 90 | V10: =K10+Q10 -> 84000 | X10: =N10+T10 -> 267 | Z10: =O10+U10 -> 133 | AB10: =SUM(AC10:AD10) -> 41400 | AC10: =SUMIFS(KH_LC!$AI:$AI,KH_LC!$AQ:$AQ,$B10&AC$6) -> 41400 | AD10: =SUMIFS(KH_LC!$AI:$AI,KH_LC!$AQ:$AQ,$B10&AD$6) -> 0 | AE10: =SUMIFS(KH_ĐL!$AT:$AT,KH_ĐL!$CF:$CF,$B10&AE$6) -> 0 | AF10: =SUMIFS(KH_ĐL!$AT:$AT,KH_ĐL!$CF:$CF,$B10&AF$6) -> 75 | AH10: =SUM(AI10:AJ10) -> 39600 | AI10: =SUMIFS(KH_LC!$AM:$AM,KH_LC!$AQ:$AQ,$B10&AI$6) -> 39600 | AJ10: =SUMIFS(KH_LC!$AM:$AM,KH_LC!$AQ:$AQ,$B10&AJ$6) -> 0 | AK10: =SUMIFS(KH_ĐL!$BF:$BF,KH_ĐL!$CF:$CF,$B10&AK$6) -> 0 | AL10: =SUMIFS(KH_ĐL!$BF:$BF,KH_ĐL!$CF:$CF,$B10&AL$6) -> 75 | AO10: 2 | AP10: PX Than 2 | AQ10: 136100 | AR10: 132000 | AS10: 3700 | AT10: 390 | AU10: 401 | AV10: 0 | AW10: 150 | AX10: =AU10+AW10 -> 551 | AY10: KT2 | AZ10: PX2 | BA10: PX Than 2 | BB10: 130100 | BC10: 125000 | BD10: 4400 | BE10: 720 | BF10: 0 | BG10: 445 | BH10: 217 | BI10: 200 | BJ10: 0 | BL10: Lọc khai thác: PX&KT
A11: 3 | B11: KT3. | C11: PX Than 3 | D11: =SUM(E11:G11) -> 125100 | E11: =SUM(L11,R11,AC11,AI11) -> 115400 | F11: =SUMIFS(KH_ĐL!$L:$L,KH_ĐL!$CF:$CF,$B11&F$6)-100 -> 9500 | G11: =SUMIFS(KH_ĐL!$L:$L,KH_ĐL!$CF:$CF,$B11&G$6)+100 -> 200 | H11: =SUM(I11:J11) -> 1107 | I11: =SUMIFS(KH_ĐL!$I:$I,KH_ĐL!$CF:$CF,$B11&I$6) -> 957 | J11: =SUMIFS(KH_ĐL!$I:$I,KH_ĐL!$CF:$CF,$B11&J$6) -> 150 | K11: =SUM(L11:M11) -> 28400 | L11: =SUMIFS(KH_LC!$AA:$AA,KH_LC!$AQ:$AQ,$B11&L$6) -> 23700 | M11: =SUMIFS(KH_LC!$AA:$AA,KH_LC!$AQ:$AQ,$B11&M$6) -> 4700 | N11: =SUMIFS(KH_ĐL!$V:$V,KH_ĐL!$CF:$CF,$B11&N$6) -> 459 | O11: =SUMIFS(KH_ĐL!$V:$V,KH_ĐL!$CF:$CF,$B11&O$6) -> 75 | Q11: =SUM(R11:S11) -> 35000 | R11: =SUMIFS(KH_LC!$AE:$AE,KH_LC!$AQ:$AQ,$B11&R$6) -> 32400 | S11: =SUMIFS(KH_LC!$AE:$AE,KH_LC!$AQ:$AQ,$B11&S$6) -> 2600 | T11: =SUMIFS(KH_ĐL!$AH:$AH,KH_ĐL!$CF:$CF,$B11&T$6) -> 290 | U11: =SUMIFS(KH_ĐL!$AH:$AH,KH_ĐL!$CF:$CF,$B11&U$6) -> 0 | V11: =K11+Q11 -> 63400 | X11: =N11+T11 -> 749 | Z11: =O11+U11 -> 75 | AB11: =SUM(AC11:AD11) -> 37000 | AC11: =SUMIFS(KH_LC!$AI:$AI,KH_LC!$AQ:$AQ,$B11&AC$6) -> 34800 | AD11: =SUMIFS(KH_LC!$AI:$AI,KH_LC!$AQ:$AQ,$B11&AD$6) -> 2200 | AE11: =SUMIFS(KH_ĐL!$AT:$AT,KH_ĐL!$CF:$CF,$B11&AE$6) -> 193 | AF11: =SUMIFS(KH_ĐL!$AT:$AT,KH_ĐL!$CF:$CF,$B11&AF$6) -> 0 | AH11: =SUM(AI11:AJ11) -> 24700 | AI11: =SUMIFS(KH_LC!$AM:$AM,KH_LC!$AQ:$AQ,$B11&AI$6) -> 24500 | AJ11: =SUMIFS(KH_LC!$AM:$AM,KH_LC!$AQ:$AQ,$B11&AJ$6) -> 200 | AK11: =SUMIFS(KH_ĐL!$BF:$BF,KH_ĐL!$CF:$CF,$B11&AK$6) -> 15 | AL11: =SUMIFS(KH_ĐL!$BF:$BF,KH_ĐL!$CF:$CF,$B11&AL$6) -> 0 | AO11: 3 | AP11: PX Than 3 | AQ11: 165600 | AR11: 157000 | AS11: 6800 | AT11: 1836 | AU11: 555 | AV11: 0 | AW11: 626 | AX11: =AU11+AW11 -> 1181 | AY11: KT3 | AZ11: PX3 | BA11: PX Than 3 | BB11: 210600 | BC11: 207000 | BD11: 2100 | BE11: 1494 | BF11: 0 | BG11: 198 | BH11: 0 | BI11: 515 | BJ11: 0 | BK11: Hai dây chuyền | BL11: Lọc đào lò: PX&ĐL& Lò
A12: 4 | B12: KT8. | C12: PX Than 8 | D12: =SUM(E12:G12) -> 181800 | E12: =SUM(L12,R12,AC12,AI12) -> 179900 | F12: =SUMIFS(KH_ĐL!$L:$L,KH_ĐL!$CF:$CF,$B12&F$6)-200 -> 1400 | G12: =SUMIFS(KH_ĐL!$L:$L,KH_ĐL!$CF:$CF,$B12&G$6) -> 500 | H12: =SUM(I12:J12) -> 552 | I12: =SUMIFS(KH_ĐL!$I:$I,KH_ĐL!$CF:$CF,$B12&I$6) -> 242 | J12: =SUMIFS(KH_ĐL!$I:$I,KH_ĐL!$CF:$CF,$B12&J$6) -> 310 | K12: =SUM(L12:M12) -> 48600 | L12: =SUMIFS(KH_LC!$AA:$AA,KH_LC!$AQ:$AQ,$B12&L$6) -> 47600 | M12: =SUMIFS(KH_LC!$AA:$AA,KH_LC!$AQ:$AQ,$B12&M$6) -> 1000 | N12: =SUMIFS(KH_ĐL!$V:$V,KH_ĐL!$CF:$CF,$B12&N$6) -> 118 | O12: =SUMIFS(KH_ĐL!$V:$V,KH_ĐL!$CF:$CF,$B12&O$6) -> 110 | Q12: =SUM(R12:S12) -> 45400 | R12: =SUMIFS(KH_LC!$AE:$AE,KH_LC!$AQ:$AQ,$B12&R$6) -> 44500 | S12: =SUMIFS(KH_LC!$AE:$AE,KH_LC!$AQ:$AQ,$B12&S$6) -> 900 | T12: =SUMIFS(KH_ĐL!$AH:$AH,KH_ĐL!$CF:$CF,$B12&T$6) -> 124 | U12: =SUMIFS(KH_ĐL!$AH:$AH,KH_ĐL!$CF:$CF,$B12&U$6) -> 100 | V12: =K12+Q12 -> 94000 | X12: =N12+T12 -> 242 | Z12: =O12+U12 -> 210 | AB12: =SUM(AC12:AD12) -> 44500 | AC12: =SUMIFS(KH_LC!$AI:$AI,KH_LC!$AQ:$AQ,$B12&AC$6) -> 44500 | AD12: =SUMIFS(KH_LC!$AI:$AI,KH_LC!$AQ:$AQ,$B12&AD$6) -> 0 | AE12: =SUMIFS(KH_ĐL!$AT:$AT,KH_ĐL!$CF:$CF,$B12&AE$6) -> 0 | AF12: =SUMIFS(KH_ĐL!$AT:$AT,KH_ĐL!$CF:$CF,$B12&AF$6) -> 40 | AH12: =SUM(AI12:AJ12) -> 43300 | AI12: =SUMIFS(KH_LC!$AM:$AM,KH_LC!$AQ:$AQ,$B12&AI$6) -> 43300 | AJ12: =SUMIFS(KH_LC!$AM:$AM,KH_LC!$AQ:$AQ,$B12&AJ$6) -> 0 | AK12: =SUMIFS(KH_ĐL!$BF:$BF,KH_ĐL!$CF:$CF,$B12&AK$6) -> 0 | AL12: =SUMIFS(KH_ĐL!$BF:$BF,KH_ĐL!$CF:$CF,$B12&AL$6) -> 60 | AO12: 4 | AP12: PX Than 4 | AQ12: 157800 | AR12: 155000 | AS12: 2500 | AT12: 265.2 | AU12: 263 | AV12: 0 | AW12: 118 | AX12: =AU12+AW12 -> 381 | AY12: KT4 | AZ12: PX4 | BA12: PX Than 4 | BB12: 162200 | BC12: 160000 | BD12: 1000 | BE12: 1170 | BF12: 0 | BG12: 122 | BH12: 0 | BI12: 325 | BJ12: 0 | BL12: Lọc xén lò: PX&XL& Xé
A13: 5 | B13: KT5. | C13: PX Than 5 | D13: =SUM(E13:G13) -> 130400 | E13: =SUM(L13,R13,AC13,AI13) -> 128000 | F13: =SUMIFS(KH_ĐL!$L:$L,KH_ĐL!$CF:$CF,$B13&F$6)+100 -> 2100 | G13: =SUMIFS(KH_ĐL!$L:$L,KH_ĐL!$CF:$CF,$B13&G$6) -> 300 | H13: =SUM(I13:J13) -> 400 | I13: =SUMIFS(KH_ĐL!$I:$I,KH_ĐL!$CF:$CF,$B13&I$6) -> 250 | J13: =SUMIFS(KH_ĐL!$I:$I,KH_ĐL!$CF:$CF,$B13&J$6) -> 150 | K13: =SUM(L13:M13) -> 31600 | L13: =SUMIFS(KH_LC!$AA:$AA,KH_LC!$AQ:$AQ,$B13&L$6) -> 30100 | M13: =SUMIFS(KH_LC!$AA:$AA,KH_LC!$AQ:$AQ,$B13&M$6) -> 1500 | N13: =SUMIFS(KH_ĐL!$V:$V,KH_ĐL!$CF:$CF,$B13&N$6) -> 153 | O13: =SUMIFS(KH_ĐL!$V:$V,KH_ĐL!$CF:$CF,$B13&O$6) -> 115 | Q13: =SUM(R13:S13) -> 36000 | R13: =SUMIFS(KH_LC!$AE:$AE,KH_LC!$AQ:$AQ,$B13&R$6) -> 35500 | S13: =SUMIFS(KH_LC!$AE:$AE,KH_LC!$AQ:$AQ,$B13&S$6) -> 500 | T13: =SUMIFS(KH_ĐL!$AH:$AH,KH_ĐL!$CF:$CF,$B13&T$6) -> 65 | U13: =SUMIFS(KH_ĐL!$AH:$AH,KH_ĐL!$CF:$CF,$B13&U$6) -> 35 | V13: =K13+Q13 -> 67600 | X13: =N13+T13 -> 218 | Z13: =O13+U13 -> 150 | AB13: =SUM(AC13:AD13) -> 32800 | AC13: =SUMIFS(KH_LC!$AI:$AI,KH_LC!$AQ:$AQ,$B13&AC$6) -> 32400 | AD13: =SUMIFS(KH_LC!$AI:$AI,KH_LC!$AQ:$AQ,$B13&AD$6) -> 400 | AE13: =SUMIFS(KH_ĐL!$AT:$AT,KH_ĐL!$CF:$CF,$B13&AE$6) -> 32 | AF13: =SUMIFS(KH_ĐL!$AT:$AT,KH_ĐL!$CF:$CF,$B13&AF$6) -> 0 | AH13: =SUM(AI13:AJ13) -> 30000 | AI13: =SUMIFS(KH_LC!$AM:$AM,KH_LC!$AQ:$AQ,$B13&AI$6) -> 30000 | AJ13: =SUMIFS(KH_LC!$AM:$AM,KH_LC!$AQ:$AQ,$B13&AJ$6) -> 0 | AK13: =SUMIFS(KH_ĐL!$BF:$BF,KH_ĐL!$CF:$CF,$B13&AK$6) -> 0 | AL13: =SUMIFS(KH_ĐL!$BF:$BF,KH_ĐL!$CF:$CF,$B13&AL$6) -> 0 | AO13: 5 | AP13: PX Than 5 | AQ13: 151200 | AR13: 146000 | AS13: 4300 | AT13: 850.2 | AU13: 447 | AV13: 0 | AW13: 268 | AX13: =AU13+AW13 -> 715 | AY13: KT5 | AZ13: PX5 | BA13: PX Than 5 | BB13: 157600 | BC13: 151500 | BD13: 5600 | BE13: 468 | BF13: 0 | BG13: 557 | BH13: 0 | BI13: 130 | BJ13: 0 | BL13: T7
A14: 6 | B14: KT6. | C14: PX Than 6 | D14: =SUM(E14:G14) -> 176300 | E14: =SUM(L14,R14,AC14,AI14) -> 170000 | F14: =SUMIFS(KH_ĐL!$L:$L,KH_ĐL!$CF:$CF,$B14&F$6)-300 -> 6000 | G14: =SUMIFS(KH_ĐL!$L:$L,KH_ĐL!$CF:$CF,$B14&G$6) -> 300 | H14: =SUM(I14:J14) -> 785 | I14: =SUMIFS(KH_ĐL!$I:$I,KH_ĐL!$CF:$CF,$B14&I$6) -> 640 | J14: =SUMIFS(KH_ĐL!$I:$I,KH_ĐL!$CF:$CF,$B14&J$6) -> 145 | K14: =SUM(L14:M14) -> 46000 | L14: =SUMIFS(KH_LC!$AA:$AA,KH_LC!$AQ:$AQ,$B14&L$6) -> 44000 | M14: =SUMIFS(KH_LC!$AA:$AA,KH_LC!$AQ:$AQ,$B14&M$6) -> 2000 | N14: =SUMIFS(KH_ĐL!$V:$V,KH_ĐL!$CF:$CF,$B14&N$6) -> 230 | O14: =SUMIFS(KH_ĐL!$V:$V,KH_ĐL!$CF:$CF,$B14&O$6) -> 15 | Q14: =SUM(R14:S14) -> 51600 | R14: =SUMIFS(KH_LC!$AE:$AE,KH_LC!$AQ:$AQ,$B14&R$6) -> 49300 | S14: =SUMIFS(KH_LC!$AE:$AE,KH_LC!$AQ:$AQ,$B14&S$6) -> 2300 | T14: =SUMIFS(KH_ĐL!$AH:$AH,KH_ĐL!$CF:$CF,$B14&T$6) -> 195 | U14: =SUMIFS(KH_ĐL!$AH:$AH,KH_ĐL!$CF:$CF,$B14&U$6) -> 30 | V14: =K14+Q14 -> 97600 | X14: =N14+T14 -> 425 | Z14: =O14+U14 -> 45 | AB14: =SUM(AC14:AD14) -> 40000 | AC14: =SUMIFS(KH_LC!$AI:$AI,KH_LC!$AQ:$AQ,$B14&AC$6) -> 38300 | AD14: =SUMIFS(KH_LC!$AI:$AI,KH_LC!$AQ:$AQ,$B14&AD$6) -> 1700 | AE14: =SUMIFS(KH_ĐL!$AT:$AT,KH_ĐL!$CF:$CF,$B14&AE$6) -> 175 | AF14: =SUMIFS(KH_ĐL!$AT:$AT,KH_ĐL!$CF:$CF,$B14&AF$6) -> 40 | AH14: =SUM(AI14:AJ14) -> 38700 | AI14: =SUMIFS(KH_LC!$AM:$AM,KH_LC!$AQ:$AQ,$B14&AI$6) -> 38400 | AJ14: =SUMIFS(KH_LC!$AM:$AM,KH_LC!$AQ:$AQ,$B14&AJ$6) -> 300 | AK14: =SUMIFS(KH_ĐL!$BF:$BF,KH_ĐL!$CF:$CF,$B14&AK$6) -> 40 | AL14: =SUMIFS(KH_ĐL!$BF:$BF,KH_ĐL!$CF:$CF,$B14&AL$6) -> 60 | AO14: 6 | AP14: PX Than 6 | AQ14: 167500 | AR14: 165000 | AS14: 2100 | AT14: 390 | AU14: 193 | AV14: 0 | AW14: 200 | AX14: =AU14+AW14 -> 393 | AY14: KT6 | AZ14: PX6 | BA14: PX Than 6 | BB14: 155300 | BC14: 150000 | BD14: 4200 | BE14: 1116 | BF14: 0 | BG14: 471 | BH14: 0 | BI14: 389 | BJ14: 0 | BL14: KHÔNG XÓA
A15: 7 | B15: CGH2. | C15: PX CGH2 | D15: =SUM(E15:G15) -> 346100 | E15: =SUM(L15,R15,AC15,AI15) -> 340000 | F15: =SUMIFS(KH_ĐL!$L:$L,KH_ĐL!$CF:$CF,$B15&F$6) -> 5800 | G15: =SUMIFS(KH_ĐL!$L:$L,KH_ĐL!$CF:$CF,$B15&G$6) -> 300 | H15: =SUM(I15:J15) -> 537 | I15: =SUMIFS(KH_ĐL!$I:$I,KH_ĐL!$CF:$CF,$B15&I$6) -> 370 | J15: =SUMIFS(KH_ĐL!$I:$I,KH_ĐL!$CF:$CF,$B15&J$6) -> 167 | K15: =SUM(L15:M15) -> 90800 | L15: =SUMIFS(KH_LC!$AA:$AA,KH_LC!$AQ:$AQ,$B15&L$6) -> 88300 | M15: =SUMIFS(KH_LC!$AA:$AA,KH_LC!$AQ:$AQ,$B15&M$6) -> 2500 | N15: =SUMIFS(KH_ĐL!$V:$V,KH_ĐL!$CF:$CF,$B15&N$6) -> 145 | O15: =SUMIFS(KH_ĐL!$V:$V,KH_ĐL!$CF:$CF,$B15&O$6) -> 70 | Q15: =SUM(R15:S15) -> 75000 | R15: =SUMIFS(KH_LC!$AE:$AE,KH_LC!$AQ:$AQ,$B15&R$6) -> 72600 | S15: =SUMIFS(KH_LC!$AE:$AE,KH_LC!$AQ:$AQ,$B15&S$6) -> 2400 | T15: =SUMIFS(KH_ĐL!$AH:$AH,KH_ĐL!$CF:$CF,$B15&T$6) -> 170 | U15: =SUMIFS(KH_ĐL!$AH:$AH,KH_ĐL!$CF:$CF,$B15&U$6) -> 25 | V15: =K15+Q15 -> 165800 | X15: =N15+T15 -> 315 | Z15: =O15+U15 -> 95 | AB15: =SUM(AC15:AD15) -> 102600 | AC15: =SUMIFS(KH_LC!$AI:$AI,KH_LC!$AQ:$AQ,$B15&AC$6) -> 101400 | AD15: =SUMIFS(KH_LC!$AI:$AI,KH_LC!$AQ:$AQ,$B15&AD$6) -> 1200 | AE15: =SUMIFS(KH_ĐL!$AT:$AT,KH_ĐL!$CF:$CF,$B15&AE$6) -> 55 | AF15: =SUMIFS(KH_ĐL!$AT:$AT,KH_ĐL!$CF:$CF,$B15&AF$6) -> 72 | AH15: =SUM(AI15:AJ15) -> 77700 | AI15: =SUMIFS(KH_LC!$AM:$AM,KH_LC!$AQ:$AQ,$B15&AI$6) -> 77700 | AJ15: =SUMIFS(KH_LC!$AM:$AM,KH_LC!$AQ:$AQ,$B15&AJ$6) -> 0 | AK15: =SUMIFS(KH_ĐL!$BF:$BF,KH_ĐL!$CF:$CF,$B15&AK$6) -> 0 | AL15: =SUMIFS(KH_ĐL!$BF:$BF,KH_ĐL!$CF:$CF,$B15&AL$6) -> 0 | AO15: 7 | AP15: PX CGH2 | AQ15: 330100 | AR15: 328000 | AS15: 2100 | AT15: 0 | AU15: 140 | AV15: 140 | AW15: 0 | AX15: =AU15+AW15 -> 140 | AY15: CGH2 | AZ15: PX7 | BA15: PX CGH2 | BB15: 350200 | BC15: 345500 | BD15: 4000 | BE15: 702 | BF15: 0 | BG15: 240 | BH15: 240 | BI15: 226 | BJ15: 0 | BK15: CGH hạng nhẹ | BL15: PX
A16: 8 | B16: CGH1. | C16: PX CGH1 | D16: =SUM(E16:G16) -> 434600 | E16: =SUM(L16,R16,AC16,AI16) -> 430000 | F16: =SUMIFS(KH_ĐL!$L:$L,KH_ĐL!$CF:$CF,$B16&F$6)+200 -> 4200 | G16: =SUMIFS(KH_ĐL!$L:$L,KH_ĐL!$CF:$CF,$B16&G$6) -> 400 | H16: =SUM(I16:J16) -> 485 | I16: =SUMIFS(KH_ĐL!$I:$I,KH_ĐL!$CF:$CF,$B16&I$6) -> 240 | J16: =SUMIFS(KH_ĐL!$I:$I,KH_ĐL!$CF:$CF,$B16&J$6) -> 245 | K16: =SUM(L16:M16) -> 106100 | L16: =SUMIFS(KH_LC!$AA:$AA,KH_LC!$AQ:$AQ,$B16&L$6) -> 103800 | M16: =SUMIFS(KH_LC!$AA:$AA,KH_LC!$AQ:$AQ,$B16&M$6) -> 2300 | N16: =SUMIFS(KH_ĐL!$V:$V,KH_ĐL!$CF:$CF,$B16&N$6) -> 120 | O16: =SUMIFS(KH_ĐL!$V:$V,KH_ĐL!$CF:$CF,$B16&O$6) -> 55 | Q16: =SUM(R16:S16) -> 129600 | R16: =SUMIFS(KH_LC!$AE:$AE,KH_LC!$AQ:$AQ,$B16&R$6) -> 129600 | S16: =SUMIFS(KH_LC!$AE:$AE,KH_LC!$AQ:$AQ,$B16&S$6) -> 0 | T16: =SUMIFS(KH_ĐL!$AH:$AH,KH_ĐL!$CF:$CF,$B16&T$6) -> 0 | U16: =SUMIFS(KH_ĐL!$AH:$AH,KH_ĐL!$CF:$CF,$B16&U$6) -> 15 | V16: =K16+Q16 -> 235700 | X16: =N16+T16 -> 120 | Z16: =O16+U16 -> 70 | AB16: =SUM(AC16:AD16) -> 75800 | AC16: =SUMIFS(KH_LC!$AI:$AI,KH_LC!$AQ:$AQ,$B16&AC$6) -> 73600 | AD16: =SUMIFS(KH_LC!$AI:$AI,KH_LC!$AQ:$AQ,$B16&AD$6) -> 2200 | AE16: =SUMIFS(KH_ĐL!$AT:$AT,KH_ĐL!$CF:$CF,$B16&AE$6) -> 120 | AF16: =SUMIFS(KH_ĐL!$AT:$AT,KH_ĐL!$CF:$CF,$B16&AF$6) -> 100 | AH16: =SUM(AI16:AJ16) -> 123100 | AI16: =SUMIFS(KH_LC!$AM:$AM,KH_LC!$AQ:$AQ,$B16&AI$6) -> 123000 | AJ16: =SUMIFS(KH_LC!$AM:$AM,KH_LC!$AQ:$AQ,$B16&AJ$6) -> 100 | AK16: =SUMIFS(KH_ĐL!$BF:$BF,KH_ĐL!$CF:$CF,$B16&AK$6) -> 0 | AL16: =SUMIFS(KH_ĐL!$BF:$BF,KH_ĐL!$CF:$CF,$B16&AL$6) -> 75 | AO16: 8 | AP16: PX CGH1 | AQ16: 439300 | AR16: 433000 | AS16: 6300 | AT16: 0 | AU16: 360 | AV16: 360 | AW16: 0 | AX16: =AU16+AW16 -> 360 | AY16: CGH1 | AZ16: PX8 | BA16: PX CGH1 | BB16: 403100 | BC16: 401000 | BD16: 1700 | BE16: 360 | BF16: 0 | BG16: 110 | BH16: 110 | BI16: 150 | BJ16: 0 | BK16: CGH hạng trung | BL16: KT1.
A17: 9 | B17: KT9. | C17: PX Than 9 | D17: =SUM(E17:G17) -> 176400 | E17: =SUM(L17,R17,AC17,AI17) -> 173700 | F17: =SUMIFS(KH_ĐL!$L:$L,KH_ĐL!$CF:$CF,$B17&F$6)-100 -> 2400 | G17: =SUMIFS(KH_ĐL!$L:$L,KH_ĐL!$CF:$CF,$B17&G$6) -> 300 | H17: =SUM(I17:J17) -> 521 | I17: =SUMIFS(KH_ĐL!$I:$I,KH_ĐL!$CF:$CF,$B17&I$6) -> 281 | J17: =SUMIFS(KH_ĐL!$I:$I,KH_ĐL!$CF:$CF,$B17&J$6) -> 240 | K17: =SUM(L17:M17) -> 46700 | L17: =SUMIFS(KH_LC!$AA:$AA,KH_LC!$AQ:$AQ,$B17&L$6) -> 46600 | M17: =SUMIFS(KH_LC!$AA:$AA,KH_LC!$AQ:$AQ,$B17&M$6) -> 100 | N17: =SUMIFS(KH_ĐL!$V:$V,KH_ĐL!$CF:$CF,$B17&N$6) -> 20 | O17: =SUMIFS(KH_ĐL!$V:$V,KH_ĐL!$CF:$CF,$B17&O$6) -> 105 | Q17: =SUM(R17:S17) -> 51300 | R17: =SUMIFS(KH_LC!$AE:$AE,KH_LC!$AQ:$AQ,$B17&R$6) -> 51200 | S17: =SUMIFS(KH_LC!$AE:$AE,KH_LC!$AQ:$AQ,$B17&S$6) -> 100 | T17: =SUMIFS(KH_ĐL!$AH:$AH,KH_ĐL!$CF:$CF,$B17&T$6) -> 0 | U17: =SUMIFS(KH_ĐL!$AH:$AH,KH_ĐL!$CF:$CF,$B17&U$6) -> 100 | V17: =K17+Q17 -> 98000 | X17: =N17+T17 -> 20 | Z17: =O17+U17 -> 205 | AB17: =SUM(AC17:AD17) -> 35300 | AC17: =SUMIFS(KH_LC!$AI:$AI,KH_LC!$AQ:$AQ,$B17&AC$6) -> 33800 | AD17: =SUMIFS(KH_LC!$AI:$AI,KH_LC!$AQ:$AQ,$B17&AD$6) -> 1500 | AE17: =SUMIFS(KH_ĐL!$AT:$AT,KH_ĐL!$CF:$CF,$B17&AE$6) -> 161 | AF17: =SUMIFS(KH_ĐL!$AT:$AT,KH_ĐL!$CF:$CF,$B17&AF$6) -> 35 | AH17: =SUM(AI17:AJ17) -> 43100 | AI17: =SUMIFS(KH_LC!$AM:$AM,KH_LC!$AQ:$AQ,$B17&AI$6) -> 42100 | AJ17: =SUMIFS(KH_LC!$AM:$AM,KH_LC!$AQ:$AQ,$B17&AJ$6) -> 1000 | AK17: =SUMIFS(KH_ĐL!$BF:$BF,KH_ĐL!$CF:$CF,$B17&AK$6) -> 100 | AL17: =SUMIFS(KH_ĐL!$BF:$BF,KH_ĐL!$CF:$CF,$B17&AL$6) -> 0 | AO17: 9 | AP17: PX Than 9 | AQ17: 145700 | AR17: 135000 | AS17: 10200 | AT17: 468 | AU17: 1060 | AV17: 0 | AW17: 158 | AX17: =AU17+AW17 -> 1218 | AY17: KT9 | AZ17: PX9 | BA17: PX Than 9 | BB17: 163500 | BC17: 159200 | BD17: 4000 | BE17: 252 | BF17: 0 | BG17: 382 | BH17: 50 | BI17: 250 | BJ17: 0 | BL17: KT2.
A18: 10 | B18: KT10. | C18: PX Than 10 | D18: =SUM(E18:G18) -> 183100 | E18: =SUM(L18,R18,AC18,AI18) -> 178600 | F18: =SUMIFS(KH_ĐL!$L:$L,KH_ĐL!$CF:$CF,$B18&F$6)-100 -> 4000 | G18: =SUMIFS(KH_ĐL!$L:$L,KH_ĐL!$CF:$CF,$B18&G$6)-100 -> 500 | H18: =SUM(I18:J18) -> 725 | I18: =SUMIFS(KH_ĐL!$I:$I,KH_ĐL!$CF:$CF,$B18&I$6) -> 465 | J18: =SUMIFS(KH_ĐL!$I:$I,KH_ĐL!$CF:$CF,$B18&J$6) -> 260 | K18: =SUM(L18:M18) -> 47200 | L18: =SUMIFS(KH_LC!$AA:$AA,KH_LC!$AQ:$AQ,$B18&L$6) -> 46600 | M18: =SUMIFS(KH_LC!$AA:$AA,KH_LC!$AQ:$AQ,$B18&M$6) -> 600 | N18: =SUMIFS(KH_ĐL!$V:$V,KH_ĐL!$CF:$CF,$B18&N$6) -> 75 | O18: =SUMIFS(KH_ĐL!$V:$V,KH_ĐL!$CF:$CF,$B18&O$6) -> 0 | Q18: =SUM(R18:S18) -> 42300 | R18: =SUMIFS(KH_LC!$AE:$AE,KH_LC!$AQ:$AQ,$B18&R$6) -> 42000 | S18: =SUMIFS(KH_LC!$AE:$AE,KH_LC!$AQ:$AQ,$B18&S$6) -> 300 | T18: =SUMIFS(KH_ĐL!$AH:$AH,KH_ĐL!$CF:$CF,$B18&T$6) -> 60 | U18: =SUMIFS(KH_ĐL!$AH:$AH,KH_ĐL!$CF:$CF,$B18&U$6) -> 0 | V18: =K18+Q18 -> 89500 | X18: =N18+T18 -> 135 | Z18: =O18+U18 -> 0 | AB18: =SUM(AC18:AD18) -> 48600 | AC18: =SUMIFS(KH_LC!$AI:$AI,KH_LC!$AQ:$AQ,$B18&AC$6) -> 46800 | AD18: =SUMIFS(KH_LC!$AI:$AI,KH_LC!$AQ:$AQ,$B18&AD$6) -> 1800 | AE18: =SUMIFS(KH_ĐL!$AT:$AT,KH_ĐL!$CF:$CF,$B18&AE$6) -> 160 | AF18: =SUMIFS(KH_ĐL!$AT:$AT,KH_ĐL!$CF:$CF,$B18&AF$6) -> 40 | AH18: =SUM(AI18:AJ18) -> 45000 | AI18: =SUMIFS(KH_LC!$AM:$AM,KH_LC!$AQ:$AQ,$B18&AI$6) -> 43200 | AJ18: =SUMIFS(KH_LC!$AM:$AM,KH_LC!$AQ:$AQ,$B18&AJ$6) -> 1800 | AK18: =SUMIFS(KH_ĐL!$BF:$BF,KH_ĐL!$CF:$CF,$B18&AK$6) -> 170 | AL18: =SUMIFS(KH_ĐL!$BF:$BF,KH_ĐL!$CF:$CF,$B18&AL$6) -> 220 | AO18: 10 | AP18: PX Than 10 | AQ18: 164300 | AR18: 163000 | AS18: 1000 | AT18: 257.4 | AU18: 108 | AV18: 0 | AW18: 116 | AX18: =AU18+AW18 -> 224 | AY18: KT10 | AZ18: PX10 | BA18: PX Than 10 | BB18: 161700 | BC18: 159000 | BD18: 2600 | BE18: 126 | BF18: 0 | BG18: 248 | BH18: 0 | BI18: 265 | BJ18: 0 | BL18: KT3.
A19: 11 | B19: KT11. | C19: PX Than 11 | D19: =SUM(E19:G19) -> 172200 | E19: =SUM(L19,R19,AC19,AI19) -> 168300 | F19: =SUMIFS(KH_ĐL!$L:$L,KH_ĐL!$CF:$CF,$B19&F$6)+100 -> 3600 | G19: =SUMIFS(KH_ĐL!$L:$L,KH_ĐL!$CF:$CF,$B19&G$6) -> 300 | H19: =SUM(I19:J19) -> 575 | I19: =SUMIFS(KH_ĐL!$I:$I,KH_ĐL!$CF:$CF,$B19&I$6) -> 370 | J19: =SUMIFS(KH_ĐL!$I:$I,KH_ĐL!$CF:$CF,$B19&J$6) -> 205 | K19: =SUM(L19:M19) -> 42900 | L19: =SUMIFS(KH_LC!$AA:$AA,KH_LC!$AQ:$AQ,$B19&L$6) -> 41200 | M19: =SUMIFS(KH_LC!$AA:$AA,KH_LC!$AQ:$AQ,$B19&M$6) -> 1700 | N19: =SUMIFS(KH_ĐL!$V:$V,KH_ĐL!$CF:$CF,$B19&N$6) -> 165 | O19: =SUMIFS(KH_ĐL!$V:$V,KH_ĐL!$CF:$CF,$B19&O$6) -> 60 | Q19: =SUM(R19:S19) -> 45700 | R19: =SUMIFS(KH_LC!$AE:$AE,KH_LC!$AQ:$AQ,$B19&R$6) -> 44400 | S19: =SUMIFS(KH_LC!$AE:$AE,KH_LC!$AQ:$AQ,$B19&S$6) -> 1300 | T19: =SUMIFS(KH_ĐL!$AH:$AH,KH_ĐL!$CF:$CF,$B19&T$6) -> 120 | U19: =SUMIFS(KH_ĐL!$AH:$AH,KH_ĐL!$CF:$CF,$B19&U$6) -> 60 | V19: =K19+Q19 -> 88600 | X19: =N19+T19 -> 285 | Z19: =O19+U19 -> 120 | AB19: =SUM(AC19:AD19) -> 43800 | AC19: =SUMIFS(KH_LC!$AI:$AI,KH_LC!$AQ:$AQ,$B19&AC$6) -> 43000 | AD19: =SUMIFS(KH_LC!$AI:$AI,KH_LC!$AQ:$AQ,$B19&AD$6) -> 800 | AE19: =SUMIFS(KH_ĐL!$AT:$AT,KH_ĐL!$CF:$CF,$B19&AE$6) -> 85 | AF19: =SUMIFS(KH_ĐL!$AT:$AT,KH_ĐL!$CF:$CF,$B19&AF$6) -> 30 | AH19: =SUM(AI19:AJ19) -> 39800 | AI19: =SUMIFS(KH_LC!$AM:$AM,KH_LC!$AQ:$AQ,$B19&AI$6) -> 39700 | AJ19: =SUMIFS(KH_LC!$AM:$AM,KH_LC!$AQ:$AQ,$B19&AJ$6) -> 100 | AK19: =SUMIFS(KH_ĐL!$BF:$BF,KH_ĐL!$CF:$CF,$B19&AK$6) -> 0 | AL19: =SUMIFS(KH_ĐL!$BF:$BF,KH_ĐL!$CF:$CF,$B19&AL$6) -> 55 | AO19: 11 | AP19: PX Than 11 | AQ19: 151800 | AR19: 144000 | AS19: 7000 | AT19: 780 | AU19: 650 | AV19: 392 | AW19: 250 | AX19: =AU19+AW19 -> 900 | AY19: KT11 | AZ19: PX11 | BA19: PX Than 11 | BB19: 165500 | BC19: 157000 | BD19: 7700 | BE19: 756 | BF19: 0 | BG19: 693 | BH19: 256 | BI19: 548 | BJ19: 0 | BL19: KT8.
A20: 12 | B20: CGĐB. | C20: PX ĐL CGĐB | D20: =SUM(E20:G20) -> 45700 | E20: =SUM(L20,R20,AC20,AI20) -> 0 | F20: =SUMIFS(KH_ĐL!$L:$L,KH_ĐL!$CF:$CF,$B20&F$6)+400 -> 45500 | G20: =SUMIFS(KH_ĐL!$L:$L,KH_ĐL!$CF:$CF,$B20&G$6) -> 200 | H20: =SUM(I20:J20) -> 3245 | I20: =SUMIFS(KH_ĐL!$I:$I,KH_ĐL!$CF:$CF,$B20&I$6) -> 2885 | J20: =SUMIFS(KH_ĐL!$I:$I,KH_ĐL!$CF:$CF,$B20&J$6) -> 360 | K20: =SUM(L20:M20) -> 10000 | L20: =SUMIFS(KH_LC!$AA:$AA,KH_LC!$AQ:$AQ,$B20&L$6) -> 0 | M20: =SUMIFS(KH_LC!$AA:$AA,KH_LC!$AQ:$AQ,$B20&M$6) -> 10000 | N20: =SUMIFS(KH_ĐL!$V:$V,KH_ĐL!$CF:$CF,$B20&N$6) -> 785 | O20: =SUMIFS(KH_ĐL!$V:$V,KH_ĐL!$CF:$CF,$B20&O$6) -> 0 | Q20: =SUM(R20:S20) -> 11000 | R20: =SUMIFS(KH_LC!$AE:$AE,KH_LC!$AQ:$AQ,$B20&R$6) -> 0 | S20: =SUMIFS(KH_LC!$AE:$AE,KH_LC!$AQ:$AQ,$B20&S$6) -> 11000 | T20: =SUMIFS(KH_ĐL!$AH:$AH,KH_ĐL!$CF:$CF,$B20&T$6) -> 675 | U20: =SUMIFS(KH_ĐL!$AH:$AH,KH_ĐL!$CF:$CF,$B20&U$6) -> 120 | V20: =K20+Q20 -> 21000 | X20: =N20+T20 -> 1460 | Z20: =O20+U20 -> 120 | AB20: =SUM(AC20:AD20) -> 11300 | AC20: =SUMIFS(KH_LC!$AI:$AI,KH_LC!$AQ:$AQ,$B20&AC$6) -> 0 | AD20: =SUMIFS(KH_LC!$AI:$AI,KH_LC!$AQ:$AQ,$B20&AD$6) -> 11300 | AE20: =SUMIFS(KH_ĐL!$AT:$AT,KH_ĐL!$CF:$CF,$B20&AE$6) -> 670 | AF20: =SUMIFS(KH_ĐL!$AT:$AT,KH_ĐL!$CF:$CF,$B20&AF$6) -> 120 | AH20: =SUM(AI20:AJ20) -> 13400 | AI20: =SUMIFS(KH_LC!$AM:$AM,KH_LC!$AQ:$AQ,$B20&AI$6) -> 0 | AJ20: =SUMIFS(KH_LC!$AM:$AM,KH_LC!$AQ:$AQ,$B20&AJ$6) -> 13400 | AK20: =SUMIFS(KH_ĐL!$BF:$BF,KH_ĐL!$CF:$CF,$B20&AK$6) -> 755 | AL20: =SUMIFS(KH_ĐL!$BF:$BF,KH_ĐL!$CF:$CF,$B20&AL$6) -> 120 | AO20: 12 | AP20: PX Đào lò 1 | AQ20: 45900 | AR20: 0 | AS20: 44600 | AT20: 1251.9 | AU20: 3058 | AV20: 0 | AW20: 566 | AX20: =AU20+AW20 -> 3624 | AY20: ĐL1 | AZ20: PX12 | BA20: PX Đào lò 1 | BB20: 47800 | BC20: 0 | BD20: 46900 | BE20: 864 | BF20: 0 | BG20: 3134 | BH20: 0 | BI20: 276 | BJ20: 0 | BL20: KT5.
A21: 13 | B21: BCG. | C21: PX ĐL BCG | D21: =SUM(E21:G21) -> 11800 | E21: =SUM(L21,R21,AC21,AI21) -> 0 | F21: =SUMIFS(KH_ĐL!$L:$L,KH_ĐL!$CF:$CF,$B21&F$6)+200 -> 10900 | G21: =SUMIFS(KH_ĐL!$L:$L,KH_ĐL!$CF:$CF,$B21&G$6) -> 900 | H21: =SUM(I21:J21) -> 2266 | I21: =SUMIFS(KH_ĐL!$I:$I,KH_ĐL!$CF:$CF,$B21&I$6) -> 1766 | J21: =SUMIFS(KH_ĐL!$I:$I,KH_ĐL!$CF:$CF,$B21&J$6) -> 500 | K21: =SUM(L21:M21) -> 2600 | L21: =SUMIFS(KH_LC!$AA:$AA,KH_LC!$AQ:$AQ,$B21&L$6) -> 0 | M21: =SUMIFS(KH_LC!$AA:$AA,KH_LC!$AQ:$AQ,$B21&M$6) -> 2600 | N21: =SUMIFS(KH_ĐL!$V:$V,KH_ĐL!$CF:$CF,$B21&N$6) -> 405 | O21: =SUMIFS(KH_ĐL!$V:$V,KH_ĐL!$CF:$CF,$B21&O$6) -> 120 | Q21: =SUM(R21:S21) -> 3300 | R21: =SUMIFS(KH_LC!$AE:$AE,KH_LC!$AQ:$AQ,$B21&R$6) -> 0 | S21: =SUMIFS(KH_LC!$AE:$AE,KH_LC!$AQ:$AQ,$B21&S$6) -> 3300 | T21: =SUMIFS(KH_ĐL!$AH:$AH,KH_ĐL!$CF:$CF,$B21&T$6) -> 416 | U21: =SUMIFS(KH_ĐL!$AH:$AH,KH_ĐL!$CF:$CF,$B21&U$6) -> 130 | V21: =K21+Q21 -> 5900 | X21: =N21+T21 -> 821 | Z21: =O21+U21 -> 250 | AB21: =SUM(AC21:AD21) -> 4400 | AC21: =SUMIFS(KH_LC!$AI:$AI,KH_LC!$AQ:$AQ,$B21&AC$6) -> 0 | AD21: =SUMIFS(KH_LC!$AI:$AI,KH_LC!$AQ:$AQ,$B21&AD$6) -> 4400 | AE21: =SUMIFS(KH_ĐL!$AT:$AT,KH_ĐL!$CF:$CF,$B21&AE$6) -> 495 | AF21: =SUMIFS(KH_ĐL!$AT:$AT,KH_ĐL!$CF:$CF,$B21&AF$6) -> 125 | AH21: =SUM(AI21:AJ21) -> 1500 | AI21: =SUMIFS(KH_LC!$AM:$AM,KH_LC!$AQ:$AQ,$B21&AI$6) -> 0 | AJ21: =SUMIFS(KH_LC!$AM:$AM,KH_LC!$AQ:$AQ,$B21&AJ$6) -> 1500 | AK21: =SUMIFS(KH_ĐL!$BF:$BF,KH_ĐL!$CF:$CF,$B21&AK$6) -> 450 | AL21: =SUMIFS(KH_ĐL!$BF:$BF,KH_ĐL!$CF:$CF,$B21&AL$6) -> 125 | AO21: 13 | AP21: PX Đào lò 2 | AQ21: 44100 | AR21: 0 | AS21: 42900 | AT21: 1246.5 | AU21: 3011 | AV21: 120 | AW21: 620 | AX21: =AU21+AW21 -> 3631 | AY21: ĐL2 | AZ21: PX13 | BA21: PX Đào lò 2 | BB21: 41000 | BC21: 0 | BD21: 39700 | BE21: 1278 | BF21: 0 | BG21: 3088 | BH21: 0 | BI21: 540 | BJ21: 0 | BL21: KT6.
A22: 14 | B22: ĐL3. | C22: PX Đào lò 3 | D22: =SUM(E22:G22) -> 32400 | E22: =SUM(L22,R22,AC22,AI22) -> 0 | F22: =SUMIFS(KH_ĐL!$L:$L,KH_ĐL!$CF:$CF,$B22&F$6)+800 -> 31800 | G22: =SUMIFS(KH_ĐL!$L:$L,KH_ĐL!$CF:$CF,$B22&G$6) -> 600 | H22: =SUM(I22:J22) -> 2611 | I22: =SUMIFS(KH_ĐL!$I:$I,KH_ĐL!$CF:$CF,$B22&I$6) -> 2411 | J22: =SUMIFS(KH_ĐL!$I:$I,KH_ĐL!$CF:$CF,$B22&J$6) -> 200 | K22: =SUM(L22:M22) -> 9800 | L22: =SUMIFS(KH_LC!$AA:$AA,KH_LC!$AQ:$AQ,$B22&L$6) -> 0 | M22: =SUMIFS(KH_LC!$AA:$AA,KH_LC!$AQ:$AQ,$B22&M$6) -> 9800 | N22: =SUMIFS(KH_ĐL!$V:$V,KH_ĐL!$CF:$CF,$B22&N$6) -> 721 | O22: =SUMIFS(KH_ĐL!$V:$V,KH_ĐL!$CF:$CF,$B22&O$6) -> 0 | Q22: =SUM(R22:S22) -> 10500 | R22: =SUMIFS(KH_LC!$AE:$AE,KH_LC!$AQ:$AQ,$B22&R$6) -> 0 | S22: =SUMIFS(KH_LC!$AE:$AE,KH_LC!$AQ:$AQ,$B22&S$6) -> 10500 | T22: =SUMIFS(KH_ĐL!$AH:$AH,KH_ĐL!$CF:$CF,$B22&T$6) -> 780 | U22: =SUMIFS(KH_ĐL!$AH:$AH,KH_ĐL!$CF:$CF,$B22&U$6) -> 0 | V22: =K22+Q22 -> 20300 | X22: =N22+T22 -> 1501 | Z22: =O22+U22 -> 0 | AB22: =SUM(AC22:AD22) -> 7500 | AC22: =SUMIFS(KH_LC!$AI:$AI,KH_LC!$AQ:$AQ,$B22&AC$6) -> 0 | AD22: =SUMIFS(KH_LC!$AI:$AI,KH_LC!$AQ:$AQ,$B22&AD$6) -> 7500 | AE22: =SUMIFS(KH_ĐL!$AT:$AT,KH_ĐL!$CF:$CF,$B22&AE$6) -> 530 | AF22: =SUMIFS(KH_ĐL!$AT:$AT,KH_ĐL!$CF:$CF,$B22&AF$6) -> 80 | AH22: =SUM(AI22:AJ22) -> 4600 | AI22: =SUMIFS(KH_LC!$AM:$AM,KH_LC!$AQ:$AQ,$B22&AI$6) -> 0 | AJ22: =SUMIFS(KH_LC!$AM:$AM,KH_LC!$AQ:$AQ,$B22&AJ$6) -> 4600 | AK22: =SUMIFS(KH_ĐL!$BF:$BF,KH_ĐL!$CF:$CF,$B22&AK$6) -> 380 | AL22: =SUMIFS(KH_ĐL!$BF:$BF,KH_ĐL!$CF:$CF,$B22&AL$6) -> 120 | AO22: 14 | AP22: PX Đào lò 3 | AQ22: 33200 | AR22: 0 | AS22: 32400 | AT22: 774 | AU22: 2870 | AV22: 241 | AW22: 565 | AX22: =AU22+AW22 -> 3435 | AY22: ĐL3 | AZ22: PX14 | BA22: PX Đào lò 3 | BB22: 38500 | BC22: 0 | BD22: 36800 | BE22: 1696.32 | BF22: 0 | BG22: 2700 | BH22: 410 | BI22: 424 | BJ22: 0 | BL22: CGH2.
A23: 15 | B23: ĐL1. | C23: PX Đào lò 1 | D23: =SUM(E23:G23) -> 34700 | E23: =SUM(L23,R23,AC23,AI23) -> 0 | F23: =SUMIFS(KH_ĐL!$L:$L,KH_ĐL!$CF:$CF,$B23&F$6)+800 -> 34700 | G23: =SUMIFS(KH_ĐL!$L:$L,KH_ĐL!$CF:$CF,$B23&G$6) -> 0 | H23: =SUM(I23:J23) -> 2660 | I23: =SUMIFS(KH_ĐL!$I:$I,KH_ĐL!$CF:$CF,$B23&I$6) -> 2225 | J23: =SUMIFS(KH_ĐL!$I:$I,KH_ĐL!$CF:$CF,$B23&J$6) -> 435 | K23: =SUM(L23:M23)-300 -> 7100 | L23: =SUMIFS(KH_LC!$AA:$AA,KH_LC!$AQ:$AQ,$B23&L$6) -> 0 | M23: =SUMIFS(KH_LC!$AA:$AA,KH_LC!$AQ:$AQ,$B23&M$6) -> 7400 | N23: =SUMIFS(KH_ĐL!$V:$V,KH_ĐL!$CF:$CF,$B23&N$6) -> 500 | O23: =SUMIFS(KH_ĐL!$V:$V,KH_ĐL!$CF:$CF,$B23&O$6) -> 110 | Q23: =SUM(R23:S23) -> 9700 | R23: =SUMIFS(KH_LC!$AE:$AE,KH_LC!$AQ:$AQ,$B23&R$6) -> 0 | S23: =SUMIFS(KH_LC!$AE:$AE,KH_LC!$AQ:$AQ,$B23&S$6) -> 9700 | T23: =SUMIFS(KH_ĐL!$AH:$AH,KH_ĐL!$CF:$CF,$B23&T$6) -> 565 | U23: =SUMIFS(KH_ĐL!$AH:$AH,KH_ĐL!$CF:$CF,$B23&U$6) -> 110 | V23: =K23+Q23 -> 16800 | X23: =N23+T23 -> 1065 | Z23: =O23+U23 -> 220 | AB23: =SUM(AC23:AD23) -> 8800 | AC23: =SUMIFS(KH_LC!$AI:$AI,KH_LC!$AQ:$AQ,$B23&AC$6) -> 0 | AD23: =SUMIFS(KH_LC!$AI:$AI,KH_LC!$AQ:$AQ,$B23&AD$6) -> 8800 | AE23: =SUMIFS(KH_ĐL!$AT:$AT,KH_ĐL!$CF:$CF,$B23&AE$6) -> 605 | AF23: =SUMIFS(KH_ĐL!$AT:$AT,KH_ĐL!$CF:$CF,$B23&AF$6) -> 110 | AH23: =SUM(AI23:AJ23) -> 8800 | AI23: =SUMIFS(KH_LC!$AM:$AM,KH_LC!$AQ:$AQ,$B23&AI$6) -> 0 | AJ23: =SUMIFS(KH_LC!$AM:$AM,KH_LC!$AQ:$AQ,$B23&AJ$6) -> 8800 | AK23: =SUMIFS(KH_ĐL!$BF:$BF,KH_ĐL!$CF:$CF,$B23&AK$6) -> 555 | AL23: =SUMIFS(KH_ĐL!$BF:$BF,KH_ĐL!$CF:$CF,$B23&AL$6) -> 105 | AO23: 15 | AP23: PX Đào lò 4 | AQ23: 40000 | AR23: 0 | AS23: 38700 | AT23: 1290 | AU23: 2910 | AV23: 435 | AW23: 600 | AX23: =AU23+AW23 -> 3510 | AY23: ĐL4 | AZ23: PX15 | BA23: PX Đào lò 4 | BB23: 37300 | BC23: 0 | BD23: 36300 | BE23: 960 | BF23: 0 | BG23: 2791 | BH23: 1398 | BI23: 557 | BJ23: 0 | BL23: CGH1.
A24: 16 | B24: ĐL5. | C24: PX Đào lò 5 | D24: =SUM(E24:G24) -> 30600 | E24: =SUM(L24,R24,AC24,AI24) -> 0 | F24: =SUMIFS(KH_ĐL!$L:$L,KH_ĐL!$CF:$CF,$B24&F$6)+1000 -> 30600 | G24: =SUMIFS(KH_ĐL!$L:$L,KH_ĐL!$CF:$CF,$B24&G$6) -> 0 | H24: =SUM(I24:J24) -> 2658 | I24: =SUMIFS(KH_ĐL!$I:$I,KH_ĐL!$CF:$CF,$B24&I$6) -> 2273 | J24: =SUMIFS(KH_ĐL!$I:$I,KH_ĐL!$CF:$CF,$B24&J$6) -> 385 | K24: =SUM(L24:M24) -> 7400 | L24: =SUMIFS(KH_LC!$AA:$AA,KH_LC!$AQ:$AQ,$B24&L$6) -> 0 | M24: =SUMIFS(KH_LC!$AA:$AA,KH_LC!$AQ:$AQ,$B24&M$6) -> 7400 | N24: =SUMIFS(KH_ĐL!$V:$V,KH_ĐL!$CF:$CF,$B24&N$6) -> 655 | O24: =SUMIFS(KH_ĐL!$V:$V,KH_ĐL!$CF:$CF,$B24&O$6) -> 0 | Q24: =SUM(R24:S24) -> 10400 | R24: =SUMIFS(KH_LC!$AE:$AE,KH_LC!$AQ:$AQ,$B24&R$6) -> 0 | S24: =SUMIFS(KH_LC!$AE:$AE,KH_LC!$AQ:$AQ,$B24&S$6) -> 10400 | T24: =SUMIFS(KH_ĐL!$AH:$AH,KH_ĐL!$CF:$CF,$B24&T$6) -> 783 | U24: =SUMIFS(KH_ĐL!$AH:$AH,KH_ĐL!$CF:$CF,$B24&U$6) -> 0 | V24: =K24+Q24 -> 17800 | X24: =N24+T24 -> 1438 | Z24: =O24+U24 -> 0 | AB24: =SUM(AC24:AD24) -> 7000 | AC24: =SUMIFS(KH_LC!$AI:$AI,KH_LC!$AQ:$AQ,$B24&AC$6) -> 0 | AD24: =SUMIFS(KH_LC!$AI:$AI,KH_LC!$AQ:$AQ,$B24&AD$6) -> 7000 | AE24: =SUMIFS(KH_ĐL!$AT:$AT,KH_ĐL!$CF:$CF,$B24&AE$6) -> 445 | AF24: =SUMIFS(KH_ĐL!$AT:$AT,KH_ĐL!$CF:$CF,$B24&AF$6) -> 150 | AH24: =SUM(AI24:AJ24) -> 5800 | AI24: =SUMIFS(KH_LC!$AM:$AM,KH_LC!$AQ:$AQ,$B24&AI$6) -> 0 | AJ24: =SUMIFS(KH_LC!$AM:$AM,KH_LC!$AQ:$AQ,$B24&AJ$6) -> 5800 | AK24: =SUMIFS(KH_ĐL!$BF:$BF,KH_ĐL!$CF:$CF,$B24&AK$6) -> 390 | AL24: =SUMIFS(KH_ĐL!$BF:$BF,KH_ĐL!$CF:$CF,$B24&AL$6) -> 235 | AO24: 16 | AP24: PX Đào lò 5 | AQ24: 29200 | AR24: 0 | AS24: 27800 | AT24: 1393.05 | AU24: 2781 | AV24: 0 | AW24: 643 | AX24: =AU24+AW24 -> 3424 | AY24: ĐL5 | AZ24: PX16 | BA24: PX Đào lò 5 | BB24: 26500 | BC24: 0 | BD24: 26500 | BE24: 0 | BF24: 0 | BG24: 2675 | BH24: 140 | BI24: 650 | BJ24: 0 | BL24: KT9.
A25: 17 | B25: ĐL6. | C25: PX Đào lò 6 | D25: =SUM(E25:G25) -> 34800 | E25: =SUM(L25,R25,AC25,AI25) -> 0 | F25: =SUMIFS(KH_ĐL!$L:$L,KH_ĐL!$CF:$CF,$B25&F$6)+200 -> 34400 | G25: =SUMIFS(KH_ĐL!$L:$L,KH_ĐL!$CF:$CF,$B25&G$6) -> 400 | H25: =SUM(I25:J25) -> 2722 | I25: =SUMIFS(KH_ĐL!$I:$I,KH_ĐL!$CF:$CF,$B25&I$6) -> 2362 | J25: =SUMIFS(KH_ĐL!$I:$I,KH_ĐL!$CF:$CF,$B25&J$6) -> 360 | K25: =SUM(L25:M25) -> 9800 | L25: =SUMIFS(KH_LC!$AA:$AA,KH_LC!$AQ:$AQ,$B25&L$6) -> 0 | M25: =SUMIFS(KH_LC!$AA:$AA,KH_LC!$AQ:$AQ,$B25&M$6) -> 9800 | N25: =SUMIFS(KH_ĐL!$V:$V,KH_ĐL!$CF:$CF,$B25&N$6) -> 560 | O25: =SUMIFS(KH_ĐL!$V:$V,KH_ĐL!$CF:$CF,$B25&O$6) -> 90 | Q25: =SUM(R25:S25) -> 10100 | R25: =SUMIFS(KH_LC!$AE:$AE,KH_LC!$AQ:$AQ,$B25&R$6) -> 0 | S25: =SUMIFS(KH_LC!$AE:$AE,KH_LC!$AQ:$AQ,$B25&S$6) -> 10100 | T25: =SUMIFS(KH_ĐL!$AH:$AH,KH_ĐL!$CF:$CF,$B25&T$6) -> 627 | U25: =SUMIFS(KH_ĐL!$AH:$AH,KH_ĐL!$CF:$CF,$B25&U$6) -> 90 | V25: =K25+Q25 -> 19900 | X25: =N25+T25 -> 1187 | Z25: =O25+U25 -> 180 | AB25: =SUM(AC25:AD25) -> 7100 | AC25: =SUMIFS(KH_LC!$AI:$AI,KH_LC!$AQ:$AQ,$B25&AC$6) -> 0 | AD25: =SUMIFS(KH_LC!$AI:$AI,KH_LC!$AQ:$AQ,$B25&AD$6) -> 7100 | AE25: =SUMIFS(KH_ĐL!$AT:$AT,KH_ĐL!$CF:$CF,$B25&AE$6) -> 578 | AF25: =SUMIFS(KH_ĐL!$AT:$AT,KH_ĐL!$CF:$CF,$B25&AF$6) -> 90 | AH25: =SUM(AI25:AJ25) -> 7800 | AI25: =SUMIFS(KH_LC!$AM:$AM,KH_LC!$AQ:$AQ,$B25&AI$6) -> 0 | AJ25: =SUMIFS(KH_LC!$AM:$AM,KH_LC!$AQ:$AQ,$B25&AJ$6) -> 7800 | AK25: =SUMIFS(KH_ĐL!$BF:$BF,KH_ĐL!$CF:$CF,$B25&AK$6) -> 597 | AL25: =SUMIFS(KH_ĐL!$BF:$BF,KH_ĐL!$CF:$CF,$B25&AL$6) -> 90 | AO25: 17 | AP25: PX Đào lò 6 | AQ25: 37300 | AR25: 0 | AS25: 37300 | AT25: 0 | AU25: 2864 | AV25: 316 | AW25: 450 | AX25: =AU25+AW25 -> 3314 | AY25: ĐL6 | AZ25: PX17 | BA25: PX Đào lò 6 | BB25: 25600 | BC25: 0 | BD25: 25300 | BE25: 270 | BF25: 0 | BG25: 2088 | BH25: 0 | BI25: 525 | BJ25: 0 | BL25: KT10.
A26: 18 | B26: XLM. | C26: C. ty XLM | D26: =SUM(E26:G26) -> 2500 | E26: =SUM(L26,R26,AC26,AI26) -> 0 | F26: =SUMIFS(KH_ĐL!$L:$L,KH_ĐL!$CF:$CF,$B26&F$6)+100 -> 2500 | G26: =SUMIFS(KH_ĐL!$L:$L,KH_ĐL!$CF:$CF,$B26&G$6) -> 0 | H26: =SUM(I26:J26) -> 3133 | I26: =SUMIFS(KH_ĐL!$I:$I,KH_ĐL!$CF:$CF,$B26&I$6) -> 3000 | J26: =SUMIFS(KH_ĐL!$I:$I,KH_ĐL!$CF:$CF,$B26&J$6) -> 133 | K26: =SUM(L26:M26) -> 0 | L26: =SUMIFS(KH_LC!$AA:$AA,KH_LC!$AQ:$AQ,$B26&L$6) -> 0 | M26: =SUMIFS(KH_LC!$AA:$AA,KH_LC!$AQ:$AQ,$B26&M$6) -> 0 | N26: =SUMIFS(KH_ĐL!$V:$V,KH_ĐL!$CF:$CF,$B26&N$6) -> 647 | O26: =SUMIFS(KH_ĐL!$V:$V,KH_ĐL!$CF:$CF,$B26&O$6) -> 120 | Q26: =SUM(R26:S26) -> 1900 | R26: =SUMIFS(KH_LC!$AE:$AE,KH_LC!$AQ:$AQ,$B26&R$6) -> 0 | S26: =SUMIFS(KH_LC!$AE:$AE,KH_LC!$AQ:$AQ,$B26&S$6) -> 1900 | T26: =SUMIFS(KH_ĐL!$AH:$AH,KH_ĐL!$CF:$CF,$B26&T$6) -> 905 | U26: =SUMIFS(KH_ĐL!$AH:$AH,KH_ĐL!$CF:$CF,$B26&U$6) -> 13 | V26: =K26+Q26 -> 1900 | X26: =N26+T26 -> 1552 | Z26: =O26+U26 -> 133 | AB26: =SUM(AC26:AD26) -> 200 | AC26: =SUMIFS(KH_LC!$AI:$AI,KH_LC!$AQ:$AQ,$B26&AC$6) -> 0 | AD26: =SUMIFS(KH_LC!$AI:$AI,KH_LC!$AQ:$AQ,$B26&AD$6) -> 200 | AE26: =SUMIFS(KH_ĐL!$AT:$AT,KH_ĐL!$CF:$CF,$B26&AE$6) -> 788 | AF26: =SUMIFS(KH_ĐL!$AT:$AT,KH_ĐL!$CF:$CF,$B26&AF$6) -> 0 | AH26: =SUM(AI26:AJ26) -> 400 | AI26: =SUMIFS(KH_LC!$AM:$AM,KH_LC!$AQ:$AQ,$B26&AI$6) -> 0 | AJ26: =SUMIFS(KH_LC!$AM:$AM,KH_LC!$AQ:$AQ,$B26&AJ$6) -> 400 | AK26: =SUMIFS(KH_ĐL!$BF:$BF,KH_ĐL!$CF:$CF,$B26&AK$6) -> 660 | AL26: =SUMIFS(KH_ĐL!$BF:$BF,KH_ĐL!$CF:$CF,$B26&AL$6) -> 0 | AO26: 18 | AP26: C. ty Xây lắp mỏ | AQ26: 10500 | AS26: 10530 | AT26: 0 | AU26: 3613.9 | AV26: 0 | AW26: 1610 | AX26: =AU26+AW26 -> 5223.9 | AY26: TN | AZ26: TN1 | BA26: C. ty Xây lắp mỏ | BB26: 0 | BC26: 0 | BD26: 0 | BE26: 0 | BF26: 0 | BG26: 3574 | BH26: 0 | BI26: 280 | BJ26: 0 | BL26: KT11.
A27: 19 | B27: TN. | C27: Thuê ngoài TKV | D27: =SUM(E27:G27) -> 37500 | E27: =SUM(L27,R27,AC27,AI27) -> 0 | F27: =SUMIFS(KH_ĐL!$L:$L,KH_ĐL!$CF:$CF,$B27&F$6)+900 -> 32500 | G27: =SUMIFS(KH_ĐL!$L:$L,KH_ĐL!$CF:$CF,$B27&G$6) -> 5000 | H27: =SUM(I27:J27) -> 6367 | I27: =SUMIFS(KH_ĐL!$I:$I,KH_ĐL!$CF:$CF,$B27&I$6) -> 3500 | J27: =SUMIFS(KH_ĐL!$I:$I,KH_ĐL!$CF:$CF,$B27&J$6) -> 2867 | K27: =SUM(L27:M27) -> 3600 | L27: =SUMIFS(KH_LC!$AA:$AA,KH_LC!$AQ:$AQ,$B27&L$6) -> 0 | M27: =SUMIFS(KH_LC!$AA:$AA,KH_LC!$AQ:$AQ,$B27&M$6) -> 3600 | N27: =SUMIFS(KH_ĐL!$V:$V,KH_ĐL!$CF:$CF,$B27&N$6) -> 245 | O27: =SUMIFS(KH_ĐL!$V:$V,KH_ĐL!$CF:$CF,$B27&O$6) -> 811 | Q27: =SUM(R27:S27) -> 13500 | R27: =SUMIFS(KH_LC!$AE:$AE,KH_LC!$AQ:$AQ,$B27&R$6) -> 0 | S27: =SUMIFS(KH_LC!$AE:$AE,KH_LC!$AQ:$AQ,$B27&S$6) -> 13500 | T27: =SUMIFS(KH_ĐL!$AH:$AH,KH_ĐL!$CF:$CF,$B27&T$6) -> 1180 | U27: =SUMIFS(KH_ĐL!$AH:$AH,KH_ĐL!$CF:$CF,$B27&U$6) -> 1140 | V27: =K27+Q27 -> 17100 | X27: =N27+T27 -> 1425 | Z27: =O27+U27 -> 1951 | AB27: =SUM(AC27:AD27) -> 13900 | AC27: =SUMIFS(KH_LC!$AI:$AI,KH_LC!$AQ:$AQ,$B27&AC$6) -> 0 | AD27: =SUMIFS(KH_LC!$AI:$AI,KH_LC!$AQ:$AQ,$B27&AD$6) -> 13900 | AE27: =SUMIFS(KH_ĐL!$AT:$AT,KH_ĐL!$CF:$CF,$B27&AE$6) -> 1330 | AF27: =SUMIFS(KH_ĐL!$AT:$AT,KH_ĐL!$CF:$CF,$B27&AF$6) -> 721 | AH27: =SUM(AI27:AJ27) -> 6500 | AI27: =SUMIFS(KH_LC!$AM:$AM,KH_LC!$AQ:$AQ,$B27&AI$6) -> 0 | AJ27: =SUMIFS(KH_LC!$AM:$AM,KH_LC!$AQ:$AQ,$B27&AJ$6) -> 6500 | AK27: =SUMIFS(KH_ĐL!$BF:$BF,KH_ĐL!$CF:$CF,$B27&AK$6) -> 745 | AL27: =SUMIFS(KH_ĐL!$BF:$BF,KH_ĐL!$CF:$CF,$B27&AL$6) -> 195 | BL27: CGĐB.
AZ28: TN2 | BA28: Thuê ngoài TKV | BB28: 23300 | BC28: 0 | BD28: 22900 | BE28: 360 | BF28: 0 | BG28: 2426 | BH28: 0 | BI28: 660 | BJ28: 0 | BL28: BCG.
BL29: ĐL3.
C30: Ghi chú: Trong quá trình triển khai thực hiện kế hoạch năm 2026 nếu có sai khác, điều kiện biến động thì căn cứ vào điều kiện thực tế Công ty sẽ có điều chỉnh phù hợp. | AP30: Ghi chú: Trong quá trình triển khai thực hiện kế hoạch năm 2025 nếu có sai khác, điều kiện biến động thì căn cứ vào điều kiện thực tế Công ty sẽ có điều chỉnh phù hợp. | BL30: ĐL1.
BL31: ĐL5.
BL32: ĐL6.
BL33: XLM.
BL34: TN.

Sheet KH_ĐL
B2: -2
B3: H/S | C3: 1.63 | CC3: Lọc khai thác: PX&KT
B4: H/S | C4: Các H/s ko xóa | O4: =120/25 -> 4.8 | P4: =O4*16 -> 76.8 | CC4: Lọc đào lò: PX&ĐL& Lò
A5: ĐL | B5: 0.735 | C5: KẾ HOẠCH ĐÀO, XÉN LÒ NĂM 2026 | BK5: BIỂU TÍNH SẢN LƯỢNG KO XOÁ, ĐIỀN DỮ LIỆU | CC5: Lọc xén lò: PX&XL& Xé | CH5: =20827-I14 -> -4573
A6: XL | B6: 0.22 | AH6: =AH13-AE13-AB13-Y13 -> 0 | AI6: =AI13-AF13-AC13-Z13 -> 10 | AT6: =AT13-AQ13-AN13-AK13 -> 0 | AU6: =AU13-AR13-AO13-AL13 -> 0 | BF6: =BF13-BC13-AZ13-AW13 -> 160 | BG6: =BG13-BD13-BA13-AX13 -> 50 | BH6: =I13-V13-AH13-AT13-BF13 -> 1075.5 | BI6: =J13-W13-AI13-AU13-BG13 -> 538 | BJ6: =L13-BN13-BR13-BV13-BZ13 -> -3300
C7: KẾ HOẠCH ĐÀO, XÉN LÒ NĂM 2027
I8: =SUBTOTAL(9,I18:I412) -> 97661.5
A9: h | B9: STT | C9: KHU VỰC, VỈA THAN, ĐƯỜNG LÒ | D9: VLC | G9: Sđ (m2) | H9: B/c (m/vì) | I9: KH NĂM 2027 | M9: LỊCH THI CÔNG | BI9: Ghi chú | BJ9: % | BK9: THAN ĐÀO, XÉN LÒ 2026
A10: =A9 -> h | I10: Tổng | J10: Đá | K10: Than | L10: SL | M10: T1 | P10: T2 | S10: T3 | V10: QI | Y10: T4 | AB10: T5 | AE10: T6 | AH10: QII | AK10: T7 | AN10: T8 | AQ10: T9 | AT10: QIII | AW10: T10 | AZ10: T11 | BC10: T12 | BF10: QIV | BJ10: =(V14+AH14)/26195 -> 0.52338232 | BK10: T1 | BL10: T2 | BM10: T3 | BN10: QI | BO10: T4 | BP10: T5 | BQ10: T6 | BR10: QII | BS10: T7 | BT10: T8 | BU10: T9 | BV10: QIII | BW10: T10 | BX10: T11 | BY10: T12 | BZ10: QIV | CC10: T7 | CD10: T8 | CE10: T9 | CF10: T10 | CG10: T11 | CH10: T12
A11: =A10 -> h | M11: Tổng | N11: Đá | O11: Than | P11: Tổng | Q11: Đá | R11: Than | S11: Tổng | T11: Đá | U11: Than | V11: Tổng | W11: Đá | X11: Than | Y11: Tổng | Z11: Đá | AA11: Than | AB11: Tổng | AC11: Đá | AD11: Than | AE11: Tổng | AF11: Đá | AG11: Than | AH11: Tổng | AI11: Đá | AJ11: Than | AK11: Tổng | AL11: Đá | AM11: Than | AN11: Tổng | AO11: Đá | AP11: Than | AQ11: Tổng | AR11: Đá | AS11: Than | AT11: Tổng | AU11: Đá | AV11: Than | AW11: Tổng | AX11: Đá | AY11: Than | AZ11: Tổng | BA11: Đá | BB11: Than | BC11: Tổng | BD11: Đá | BE11: Than | BF11: Tổng | BG11: Đá | BH11: Than | BJ11: =(V14+AH14)/I14 -> 0.53976378
A12: =A11 -> h | B12: a | C12: 2 | D12: 3 | G12: 4 | H12: 5 | I12: 6 | J12: 7 | K12: 8 | L12: 12 | BI12: 29
A13: =A12 -> h | B13: a | C13: TỔNG CỘNG (A+B) | I13: =I16+I319+I379 -> 32862.5 | J13: =J16+J319+J379 -> 12489.5 | K13: =K16+K319+K379 -> 20373 | L13: =L16+L319+L379 -> 276800 | M13: =M16+M319+M379 -> 2983.5 | N13: =N16+N319+N379 -> 1185 | O13: =O16+O319+O379 -> 1798.5 | P13: =P16+P319+P379 -> 2222.5 | ... BH13: =BH16+BH319+BH379 -> 3867 | BI13: =(V14+AH14)/I14 -> 0.53976378 | BK13: =BK16+BK319+BK379 -> 25200 | BL13: =BL16+BL319+BL379 -> 19500 | BM13: =BM16+BM319+BM379 -> 27200 | BN13: =BN16+BN319+BN379 -> 70800 | BO13: =BO16+BO319+BO379 -> 27900 | BP13: =BP16+BP319+BP379 -> 27800 | BQ13: =BQ16+BQ319+BQ379 -> 27500 | BR13: =BR16+BR319+BR379 -> 81800 | ... BZ13: =BZ16+BZ319+BZ379 -> 53600 | CA13: =BZ13+BV13+BR13+BN13 -> 280100 | CB13: =IF(SUM(I13:L13)<>0,"X") -> X | CC13: KHÔNG XÓA
A14: =#REF! -> #REF! | B14: a | C14: ĐL CBSX | I14: =I18+I31+I45+I62+I77+I92+I107+I117+I127+I139+I149+I166+I191+I215+I243+I267+I293+I320+I380 -> 25400 | J14: =J18+J31+J45+J62+J77+J92+J107+J117+J127+J139+J149+J166+J191+J215+J243+J267+J293+J320+J380 -> 8421 | K14: =K18+K31+K45+K62+K77+K92+K107+K117+K127+K139+K149+K166+K191+K215+K243+K267+K293+K320+K380 -> 16979 | L14: =L18+L31+L45+L62+L77+L92+L107+L117+L127+L139+L149+L166+L191+L215+L243+L267+L293+L320+L380 -> 269100 | M14: =M18+M31+M45+M62+M77+M92+M107+M117+M127+M139+M149+M166+M191+M215+M243+M267+M293+M320+M380 -> 2400 | N14: =N18+N31+N45+N62+N77+N92+N107+N117+N127+N139+N149+N166+N191+N215+N243+N267+N293+N320+N380 -> 860 | O14: =O18+O31+O45+O62+O77+O92+O107+O117+O127+O139+O149+O166+O191+O215+O243+O267+O293+O320+O380 -> 1540 | P14: =P18+P31+P45+P62+P77+P92+P107+P117+P127+P139+P149+P166+P191+P215+P243+P267+P293+P320+P380 -> 1730 | ... BH14: =BH18+BH31+BH45+BH62+BH77+BH92+BH107+BH117+BH127+BH139+BH149+BH166+BH191+BH215+BH243+BH267+BH293+BH320+BH380 -> 3312 | BI14: =(V14+AH14)/26300 -> 0.52129278 | BJ14: PX | BK14: =BK18+BK31+BK45+BK62+BK77+BK92+BK107+BK117+BK127+BK139+BK149+BK166+BK191+BK215+BK243+BK267+BK293+BK320+BK380 -> 24300 | BL14: =BL18+BL31+BL45+BL62+BL77+BL92+BL107+BL117+BL127+BL139+BL149+BL166+BL191+BL215+BL243+BL267+BL293+BL320+BL380 -> 18500 | BM14: =BM18+BM31+BM45+BM62+BM77+BM92+BM107+BM117+BM127+BM139+BM149+BM166+BM191+BM215+BM243+BM267+BM293+BM320+BM380 -> 26400 | BN14: =BN18+BN31+BN45+BN62+BN77+BN92+BN107+BN117+BN127+BN139+BN149+BN166+BN191+BN215+BN243+BN267+BN293+BN320+BN380 -> 68200 | BO14: =BO18+BO31+BO45+BO62+BO77+BO92+BO107+BO117+BO127+BO139+BO149+BO166+BO191+BO215+BO243+BO267+BO293+BO320+BO380 -> 26900 | BP14: =BP18+BP31+BP45+BP62+BP77+BP92+BP107+BP117+BP127+BP139+BP149+BP166+BP191+BP215+BP243+BP267+BP293+BP320+BP380 -> 26700 | BQ14: =BQ18+BQ31+BQ45+BQ62+BQ77+BQ92+BQ107+BQ117+BQ127+BQ139+BQ149+BQ166+BQ191+BQ215+BQ243+BQ267+BQ293+BQ320+BQ380 -> 26700 | BR14: =BR18+BR31+BR45+BR62+BR77+BR92+BR107+BR117+BR127+BR139+BR149+BR166+BR191+BR215+BR243+BR267+BR293+BR320+BR380 -> 78900 | ... BZ14: =BZ18+BZ31+BZ45+BZ62+BZ77+BZ92+BZ107+BZ117+BZ127+BZ139+BZ149+BZ166+BZ191+BZ215+BZ243+BZ267+BZ293+BZ320+BZ380 -> 51600 | CA14: =(V14+AH14)*100/26600 -> 51.541353 | CB14: =IF(SUM(I14:L14)<>0,"X") -> X | CG14: =I14-V14-AH14-AT14-BF14 -> 0
A15: =A14 -> #REF! | B15: a | C15: XL CBSX | D15: =BG15/BF15 -> 0.60625 | I15: =I26+I39+I56+I72+I86+I102+I112+I123+I135+I145+I161+I185+I207+I236+I261+I287+I313+I369+I397 -> 7500 | J15: =J26+J39+J56+J72+J86+J102+J112+J123+J135+J145+J161+J185+J207+J236+J261+J287+J313+J369+J397 -> 4086 | K15: =K26+K39+K56+K72+K86+K102+K112+K123+K135+K145+K161+K185+K207+K236+K261+K287+K313+K369+K397 -> 3414 | L15: =L26+L39+L56+L72+L86+L102+L112+L123+L135+L145+L161+L185+L207+L236+L261+L287+L313+L369+L397 -> 10700 | M15: =M26+M39+M56+M72+M86+M102+M112+M123+M135+M145+M161+M185+M207+M236+M261+M287+M313+M369+M397 -> 619 | N15: =N26+N39+N56+N72+N86+N102+N112+N123+N135+N145+N161+N185+N207+N236+N261+N287+N313+N369+N397 -> 330 | O15: =O26+O39+O56+O72+O86+O102+O112+O123+O135+O145+O161+O185+O207+O236+O261+O287+O313+O369+O397 -> 289 | P15: =P26+P39+P56+P72+P86+P102+P112+P123+P135+P145+P161+P185+P207+P236+P261+P287+P313+P369+P397 -> 575 | ... BH15: =BH26+BH39+BH56+BH72+BH86+BH102+BH112+BH123+BH135+BH145+BH161+BH185+BH207+BH236+BH261+BH287+BH313+BH369+BH397 -> 630 | BJ15: PX | BK15: =BK26+BK39+BK56+BK72+BK86+BK102+BK112+BK123+BK135+BK145+BK161+BK185+BK207+BK236+BK261+BK287+BK313+BK369+BK397 -> 900 | BL15: =BL26+BL39+BL56+BL72+BL86+BL102+BL112+BL123+BL135+BL145+BL161+BL185+BL207+BL236+BL261+BL287+BL313+BL369+BL397 -> 1000 | BM15: =BM26+BM39+BM56+BM72+BM86+BM102+BM112+BM123+BM135+BM145+BM161+BM185+BM207+BM236+BM261+BM287+BM313+BM369+BM397 -> 800 | BN15: =BN26+BN39+BN56+BN72+BN86+BN102+BN112+BN123+BN135+BN145+BN161+BN185+BN207+BN236+BN261+BN287+BN313+BN369+BN397 -> 2600 | BO15: =BO26+BO39+BO56+BO72+BO86+BO102+BO112+BO123+BO135+BO145+BO161+BO185+BO207+BO236+BO261+BO287+BO313+BO369+BO397 -> 1000 | BP15: =BP26+BP39+BP56+BP72+BP86+BP102+BP112+BP123+BP135+BP145+BP161+BP185+BP207+BP236+BP261+BP287+BP313+BP369+BP397 -> 1100 | BQ15: =BQ26+BQ39+BQ56+BQ72+BQ86+BQ102+BQ112+BQ123+BQ135+BQ145+BQ161+BQ185+BQ207+BQ236+BQ261+BQ287+BQ313+BQ369+BQ397 -> 800 | BR15: =BR26+BR39+BR56+BR72+BR86+BR102+BR112+BR123+BR135+BR145+BR161+BR185+BR207+BR236+BR261+BR287+BR313+BR369+BR397 -> 3100 | ... BZ15: =BZ26+BZ39+BZ56+BZ72+BZ86+BZ102+BZ112+BZ123+BZ135+BZ145+BZ161+BZ185+BZ207+BZ236+BZ261+BZ287+BZ313+BZ369+BZ397 -> 2000 | CB15: =IF(SUM(I15:L15)<>0,"X") -> X
A16: =A15 -> #REF! | B16: A | C16: PHẦN TỰ LÀM | I16: =I17+I30+I44+I61+I76+I91+I106+I116+I126+I138+I148+I165+I190+I214+I242+I266+I292 -> 23362.5 | J16: =J17+J30+J44+J61+J76+J91+J106+J116+J126+J138+J148+J165+J190+J214+J242+J266+J292 -> 6935.5 | K16: =K17+K30+K44+K61+K76+K91+K106+K116+K126+K138+K148+K165+K190+K214+K242+K266+K292 -> 16427 | L16: =L17+L30+L44+L61+L76+L91+L106+L116+L126+L138+L148+L165+L190+L214+L242+L266+L292 -> 237800 | M16: =M17+M30+M44+M61+M76+M91+M106+M116+M126+M138+M148+M165+M190+M214+M242+M266+M292 -> 2508 | N16: =N17+N30+N44+N61+N76+N91+N106+N116+N126+N138+N148+N165+N190+N214+N242+N266+N292 -> 830 | O16: =O17+O30+O44+O61+O76+O91+O106+O116+O126+O138+O148+O165+O190+O214+O242+O266+O292 -> 1678 | P16: =P17+P30+P44+P61+P76+P91+P106+P116+P126+P138+P148+P165+P190+P214+P242+P266+P292 -> 1801 | ... BH16: =BH17+BH30+BH44+BH61+BH76+BH91+BH106+BH116+BH126+BH138+BH148+BH165+BH190+BH214+BH242+BH266+BH292 -> 3322 | BJ16: PX | BK16: =BK17+BK30+BK44+BK61+BK76+BK91+BK106+BK116+BK126+BK138+BK148+BK165+BK190+BK214+BK242+BK266+BK292 -> 24500 | BL16: =BL17+BL30+BL44+BL61+BL76+BL91+BL106+BL116+BL126+BL138+BL148+BL165+BL190+BL214+BL242+BL266+BL292 -> 18500 | BM16: =BM17+BM30+BM44+BM61+BM76+BM91+BM106+BM116+BM126+BM138+BM148+BM165+BM190+BM214+BM242+BM266+BM292 -> 25300 | BN16: =BN17+BN30+BN44+BN61+BN76+BN91+BN106+BN116+BN126+BN138+BN148+BN165+BN190+BN214+BN242+BN266+BN292 -> 67200 | BO16: =BO17+BO30+BO44+BO61+BO76+BO91+BO106+BO116+BO126+BO138+BO148+BO165+BO190+BO214+BO242+BO266+BO292 -> 22800 | BP16: =BP17+BP30+BP44+BP61+BP76+BP91+BP106+BP116+BP126+BP138+BP148+BP165+BP190+BP214+BP242+BP266+BP292 -> 22600 | BQ16: =BQ17+BQ30+BQ44+BQ61+BQ76+BQ91+BQ106+BQ116+BQ126+BQ138+BQ148+BQ165+BQ190+BQ214+BQ242+BQ266+BQ292 -> 22400 | BR16: =BR17+BR30+BR44+BR61+BR76+BR91+BR106+BR116+BR126+BR138+BR148+BR165+BR190+BR214+BR242+BR266+BR292 -> 66700 | ... BZ16: =BZ17+BZ30+BZ44+BZ61+BZ76+BZ91+BZ106+BZ116+BZ126+BZ138+BZ148+BZ165+BZ190+BZ214+BZ242+BZ266+BZ292 -> 47000 | CB16: =IF(SUM(I16:L16)<>0,"X") -> X | CC16: PX | CD16: Tiết diện | CE16: Lò đào, xén
A17: =A16 -> #REF! | B17: 1 | C17: PX KT1 | I17: =SUM(I18:I29)/2 -> 1001 | J17: =SUM(J18:J29)/2 -> 246 | K17: =SUM(K18:K29)/2 -> 755 | L17: =SUM(L18:L27)/2 -> 8900 | M17: =SUM(M18:M29)/2 -> 160 | N17: =SUM(N18:N29)/2 -> 35 | O17: =SUM(O18:O29)/2 -> 125 | P17: =SUM(P18:P29)/2 -> 50 | Q17: =SUM(Q18:Q29)/2 -> 15 | R17: =SUM(R18:R29)/2 -> 35 | S17: =SUM(S18:S29)/2 -> 120 | T17: =SUM(T18:T29)/2 -> 30 | ... X17: =SUM(X18:X29)/2 -> 250 | Y17: =SUM(Y18:Y27)/2 -> 65 | Z17: =SUM(Z18:Z27)/2 -> 18 | AA17: =SUM(AA18:AA27)/2 -> 47 | AB17: =SUM(AB18:AB27)/2 -> 70 | AC17: =SUM(AC18:AC27)/2 -> 20 | AD17: =SUM(AD18:AD27)/2 -> 50 | AE17: =SUM(AE18:AE27)/2 -> 60 | AF17: =SUM(AF18:AF27)/2 -> 18 | ... BH17: =SUM(BH18:BH27)/2 -> 140 | BJ17: =LEFT(C17,2) -> PX | BK17: =SUM(BK18:BK29)/2 -> 1300 | BL17: =SUM(BL18:BL29)/2 -> 500 | BM17: =SUM(BM18:BM29)/2 -> 1100 | BN17: =SUM(BN18:BN29)/2 -> 2900 | BO17: =SUM(BO18:BO29)/2 -> 600 | BP17: =SUM(BP18:BP29)/2 -> 600 | BQ17: =SUM(BQ18:BQ29)/2 -> 600 | BR17: =SUM(BR18:BR29)/2 -> 1800 | ... BZ17: =SUM(BZ18:BZ29)/2 -> 1500 | CB17: =IF(SUM(I17:L17)<>0,"X") -> X | CC17: KT1. | CD17: =CC17&G17 -> KT1. | CE17: =LEFT(C17,2) -> PX | CF17: =CC17&CE17 -> KT1.PX
A18: =#REF! -> #REF! | B18: a | C18: ĐL CBSX (Đào lò) | I18: =SUM(I19:I25) -> 896 | J18: =SUM(J19:J25) -> 201 | K18: =SUM(K19:K25) -> 695 | L18: =SUM(L19:L25) -> 8700 | M18: =SUM(M19:M25) -> 120 | N18: =SUM(N19:N25) -> 25 | O18: =SUM(O19:O25) -> 95 | P18: =SUM(P19:P25) -> 50 | ... BH18: =SUM(BH19:BH25) -> 110 | BJ18: =LEFT(C18,2) -> ĐL | BK18: =SUM(BK19:BK25) -> 1200 | BL18: =SUM(BL19:BL25) -> 500 | BM18: =SUM(BM19:BM25) -> 1100 | BN18: =SUM(BN19:BN25) -> 2800 | BO18: =SUM(BO19:BO25) -> 600 | BP18: =SUM(BP19:BP25) -> 600 | BQ18: =SUM(BQ19:BQ25) -> 600 | BR18: =SUM(BR19:BR25) -> 1800 | ... BZ18: =SUM(BZ19:BZ25) -> 1400 | CA18: =I18-V18-AH18-AT18-BF18 -> 0 | CB18: =IF(SUM(I18:L18)<>0,"X") -> X | CC18: =CC17 -> KT1. | CD18: =CC18&G18 -> KT1. | CE18: =LEFT(C18,2) -> ĐL | CF18: =CC18&CE18 -> KT1.ĐL
A19: =A18 -> #REF! | C19: Lò SSC+PRT chợ N-8-3 | D19: Thép | G19: 9.5 | H19: 0.7 | I19: =V19+AH19+AT19+BF19 -> 361 | J19: =W19+AI19+AU19+BG19 -> 70 | K19: =X19+AJ19+AV19+BH19 -> 291 | L19: =BN19+BR19+BV19+BZ19 -> 3300 | M19: 60 | N19: 10 | O19: =M19-N19 -> 50 | R19: =P19-Q19 -> 0 | S19: 60 | T19: 15 | U19: =S19-T19 -> 45 | V19: =W19+X19 -> 120 | W19: =N19+Q19+T19 -> 25 | X19: =O19+R19+U19 -> 95 | AA19: =Y19-Z19 -> 0 | AB19: 60 | AC19: 15 | AD19: =AB19-AC19 -> 45 | AG19: =AE19-AF19 -> 0 | AH19: =Y19+AB19+AE19 -> 60 | AI19: =Z19+AC19+AF19 -> 15 | AJ19: =AA19+AD19+AG19 -> 45 | AK19: 61 | AL19: 15 | AM19: =AK19-AL19 -> 46 | AP19: =AN19-AO19 -> 0 | AQ19: 60 | AR19: 5 | AS19: =AQ19-AR19 -> 55 | AT19: =AK19+AN19+AQ19 -> 121 | AU19: =AL19+AO19+AR19 -> 20 | AV19: =AM19+AP19+AS19 -> 101 | AW19: 60 | AX19: 10 | AY19: =AW19-AX19 -> 50 | BB19: =AZ19-BA19 -> 0 | BE19: =BC19-BD19 -> 0 | BF19: =AW19+AZ19+BC19 -> 60 | BG19: =AX19+BA19+BD19 -> 10 | BH19: =AY19+BB19+BE19 -> 50 | BJ19: =LEFT(C19,2) -> Lò | BK19: =ROUND(O19*G19*$C$3*$B$5,-2) -> 600 | BL19: =ROUND(R19*G19*$C$3*$B$5,-2) -> 0 | BM19: =ROUND(U19*G19*$C$3*$B$5,-2) -> 500 | BN19: =ROUND(X19*G19*$C$3*$B$5,-2) -> 1100 | BO19: =ROUND(AA19*G19*$C$3*$B$5,-2) -> 0 | BP19: =ROUND(AD19*G19*$C$3*$B$5,-2) -> 500 | BQ19: =ROUND(AG19*G19*$C$3*$B$5,-2) -> 0 | BR19: =ROUND(AJ19*G19*$B$5*$C$3,-2) -> 500 | BS19: =ROUND(AM19*G19*$C$3*$B$5,-2) -> 500 | BT19: =ROUND(AP19*G19*$C$3*$B$5,-2) -> 0 | BU19: =ROUND(AS19*G19*$C$3*$B$5,-2) -> 600 | BV19: =ROUND(AV19*G19*$C$3*$B$5,-2) -> 1100 | BW19: =ROUND(AY19*G19*$C$3*$B$5,-2) -> 600 | BX19: =ROUND(BB19*G19*$C$3*$B$5,-2) -> 0 | BY19: =ROUND(BE19*G19*$C$3*$B$5,-2) -> 0 | BZ19: =ROUND(BH19*G19*$C$3*$B$5,-2) -> 600 | CB19: =IF(SUM(I19:L19)<>0,"X") -> X | CC19: =CC18 -> KT1. | CD19: =CC19&G19 -> KT1.9,5 | CE19: =LEFT(C19,2) -> Lò | CF19: =CC19&CE19 -> KT1.Lò
A20: =A19 -> #REF! | C20: Lò BX+ DVVT chợ N-8-4A | D20: Thép | G20: 11.2 | H20: 0.7 | I20: =V20+AH20+AT20+BF20 -> 420 | J20: =W20+AI20+AU20+BG20 -> 111 | K20: =X20+AJ20+AV20+BH20 -> 309 | L20: =BN20+BR20+BV20+BZ20 -> 4200 | M20: 60 | N20: 15 | O20: =M20-N20 -> 45 | P20: 50 | Q20: 15 | R20: =P20-Q20 -> 35 | S20: 60 | T20: 15 | U20: =S20-T20 -> 45 | V20: =M20+P20+S20 -> 170 | W20: =N20+Q20+T20 -> 45 | X20: =O20+R20+U20 -> 125 | Y20: 65 | Z20: 18 | AA20: =Y20-Z20 -> 47 | AB20: 10 | AC20: 5 | AD20: =AB20-AC20 -> 5 | AE20: 60 | AF20: 18 | AG20: =AE20-AF20 -> 42 | AH20: =Y20+AB20+AE20 -> 135 | AI20: =Z20+AC20+AF20 -> 41 | AJ20: =AA20+AD20+AG20 -> 94 | AK20: 60 | AL20: 15 | AM20: =AK20-AL20 -> 45 | AN20: 55 | AO20: 10 | AP20: =AN20-AO20 -> 45 | AS20: =AQ20-AR20 -> 0 | AT20: =AK20+AN20+AQ20 -> 115 | AU20: =AL20+AO20+AR20 -> 25 | AV20: =AM20+AP20+AS20 -> 90 | AY20: =AW20-AX20 -> 0 | BB20: =AZ20-BA20 -> 0 | BE20: =BC20-BD20 -> 0 | BF20: =AW20+AZ20+BC20 -> 0 | BG20: =AX20+BA20+BD20 -> 0 | BH20: =AY20+BB20+BE20 -> 0 | BJ20: =LEFT(C20,2) -> Lò | BK20: =ROUND(O20*G20*$C$3*$B$5,-2) -> 600 | BL20: =ROUND(R20*G20*$C$3*$B$5,-2) -> 500 | BM20: =ROUND(U20*G20*$C$3*$B$5,-2) -> 600 | BN20: =ROUND(X20*G20*$C$3*$B$5,-2) -> 1700 | BO20: =ROUND(AA20*G20*$C$3*$B$5,-2) -> 600 | BP20: =ROUND(AD20*G20*$C$3*$B$5,-2) -> 100 | BQ20: =ROUND(AG20*G20*$C$3*$B$5,-2) -> 600 | BR20: =ROUND(AJ20*G20*$B$5*$C$3,-2) -> 1300 | BS20: =ROUND(AM20*G20*$C$3*$B$5,-2) -> 600 | BT20: =ROUND(AP20*G20*$C$3*$B$5,-2) -> 600 | BU20: =ROUND(AS20*G20*$C$3*$B$5,-2) -> 0 | BV20: =ROUND(AV20*G20*$C$3*$B$5,-2) -> 1200 | BW20: =ROUND(AY20*G20*$C$3*$B$5,-2) -> 0 | BX20: =ROUND(BB20*G20*$C$3*$B$5,-2) -> 0 | BY20: =ROUND(BE20*G20*$C$3*$B$5,-2) -> 0 | BZ20: =ROUND(BH20*G20*$C$3*$B$5,-2) -> 0 | CB20: =IF(SUM(I20:L20)<>0,"X") -> X | CC20: =CC19 -> KT1. | CD20: =CC20&G20 -> KT1.11,2 | CE20: =LEFT(C20,2) -> Lò | CF20: =CC20&CE20 -> KT1.Lò
